Workbook

Sheet raw-scores
A1: BASELINE (PRE) | ED1: ENDLINE (POST)
A2: Participants | B2: Groups | C2: PCL5-5 with LEC-5 | R2: PTSD Diagnostic and statistical manual of mental disorders (5th edition - DSM-5) check list (PCL-5) 20 items | AM2: PTSD Havard Trauma Questionnaire (HTQ) 40 items | CC2: PRIMARY CARE PTSD Screen for DSM-5 (PC-PTSD) | CJ2: Mental Health wellbeing (WEMWBS) | CY2: The 10-item CD-RISC | DJ2: Brief Resilience Scale (BRS) 6 items | DR2: General self efficacy (GSE) 10 items | ED2: PCL5-5 with LEC-5 | FN2: PTSD Havard Trauma Questionnaire | HD2: PRIMARY CARE PTSD Screen for DSM-5 | HK2: Mental Health wellbeing (WEMWBS) | HZ2: The 10-item CD-RISC | IK2: Brief Resilience Scale (BRS) | IS2: General self efficacy
C3: Item 1 | D3: Item 2 | E3: Item 3 | F3: Item 4 | G3: Item 5 | H3: Item 6 | I3: Item 7 | J3: Item 8 | K3: Item 9 | L3: Item 10 | M3: Item 11 | N3: Item 12 | O3: Item 13 | P3: Item 14 | R3: Item 1 | S3: Item 2 | T3: Item 3 | U3: Item 4 | V3: Item 5 | W3: Item 6 | X3: Item 7 | Y3: Item 8 | Z3: Item 9 | AA3: Item 10 | AB3: Item 11 | AC3: Item 12 | AD3: Item 13 | AE3: Item 14 | AF3: Item 15 | AG3: Item 16 | AH3: Item 17 | AI3: Item 18 | AJ3: Item 19 | AK3: Item 20 | AL3: TOTAL | AM3: Item 1 | AN3: Item 2 | AO3: Item 3 | AP3: Item 4 | AQ3: Item 5 | AR3: Item 6 | AS3: Item 7 | AT3: Item 8 | AU3: Item 9 | AV3: Item 10 | AW3: Item 11 | AX3: Item 12 | AY3: Item 13 | AZ3: Item 14 | BA3: Item 15 | BB3: Item 16 | BC3: Item 17 | BD3: Item 18 | BE3: Item 19 | BF3: Item 20 | BG3: Item 21 | BH3: Item 22 | BI3: Item 23 | BJ3: Item 24 | BK3: Item 25 | BL3: Item 26 | BM3: Item 27 | BN3: Item 28 | BO3: Item 29 | BP3: Item 30 | BQ3: Item 31 | BR3: Item 32 | BS3: Item 33 | BT3: Item 34 | BU3: Item 35 | BV3: Item 36 | BW3: Item 37 | BX3: Item 38 | BY3: Item 39 | BZ3: Item 40 | CA3: TOTAL | CD3: Item 1 | CE3: Item 2 | CF3: Item 3 | CG3: Item 4 | CH3: Item 5 | CI3: TOTAL | CJ3: Item 1 | CK3: Item 2 | CL3: Item 3 | CM3: Item 4 | CN3: Item 5 | CO3: Item 6 | CP3: Item 7 | CQ3: Item 8 | CR3: Item 9 | CS3: Item 10 | CT3: Item 11 | CU3: Item 12 | CV3: Item 13 | CW3: Item 14 | CX3: TOTAL | CY3: Item 1 | CZ3: Item 2 | DA3: Item 3 | DB3: Item 4 | DC3: Item 5 | DD3: Item 6 | DE3: Item 7 | DF3: Item 8 | DG3: Item 9 | DH3: Item 10 | DI3: TOTAL | DJ3: Item 1 | DK3: Item 2 | DL3: Item 3 | DM3: Item 4 | DN3: Item 5 | DO3: Item 6 | DP3: TOTAL | DR3: Item 1 | DS3: Item 2 | DT3: Item 3 | DU3: Item 4 | DV3: Item 5 | DW3: Item 6 | DX3: Item 7 | DY3: Item 8 | DZ3: Item 9 | EA3: Item 10 | EB3: TOTAL | ED3: Item 1 | EE3: Item 2 | EF3: Item 3 | EG3: Item 4 | EH3: Item 5 | EI3: Item 6 | EJ3: Item 7 | EK3: Item 8 | EL3: Item 9 | EM3: Item 10 | EN3: Item 11 | EO3: Item 12 | EP3: Item 13 | EQ3: Item 14 | ER3: TOTAL | ES3: Item 1 | ET3: Item 2 | EU3: Item 3 | EV3: Item 4 | EW3: Item 5 | EX3: Item 6 | EY3: Item 7 | EZ3: Item 8 | FA3: Item 9 | FB3: Item 10 | FC3: Item 11 | FD3: Item 12 | FE3: Item 13 | FF3: Item 14 | FG3: Item 15 | FH3: Item 16 | FI3: Item 17 | FJ3: Item 18 | FK3: Item 19 | FL3: Item 20 | FM3: TOTAL | FN3: Item 1 | FO3: Item 2 | FP3: Item 3 | FQ3: Item 4 | FR3: Item 5 | FS3: Item 6 | FT3: Item 7 | FU3: Item 8 | FV3: Item 9 | FW3: Item 10 | FX3: Item 11 | FY3: Item 12 | FZ3: Item 13 | GA3: Item 14 | GB3: Item 15 | GC3: Item 16 | GD3: Item 17 | GE3: Item 18 | GF3: Item 19 | GG3: Item 20 | GH3: Item 21 | GI3: Item 22 | GJ3: Item 23 | GK3: Item 24 | GL3: Item 25 | GM3: Item 26 | GN3: Item 27 | GO3: Item 28 | GP3: Item 29 | GQ3: Item 30 | GR3: Item 31 | GS3: Item 32 | GT3: Item 33 | GU3: Item 34 | GV3: Item 35 | GW3: Item 36 | GX3: Item 37 | GY3: Item 38 | GZ3: Item 39 | HA3: Item 40 | HB3: TOTAL | HK3: Item 1 | HL3: Item 2 | HM3: Item 3 | HN3: Item 4 | HO3: Item 5 | HP3: Item 6 | HQ3: Item 7 | HR3: Item 8 | HS3: Item 9 | HT3: Item 10 | HU3: Item 11 | HV3: Item 12 | HW3: Item 13 | HX3: Item 14 | HY3: TOTAL | HZ3: Item 1 | IA3: Item 2 | IB3: Item 3 | IC3: Item 4 | ID3: Item 5 | IE3: Item 6 | IF3: Item 7 | IG3: Item 8 | IH3: Item 9 | II3: Item 10 | IJ3: TOTAL | IK3: Item 1 | IL3: Item 2 | IM3: Item 3 | IN3: Item 4 | IO3: Item 5 | IP3: Item 6 | IQ3: TOTAL | IS3: Item 1 | IT3: Item 2 | IU3: Item 3 | IV3: Item 4 | IW3: Item 5 | IX3: Item 6 | IY3: Item 7 | IZ3: Item 8 | JA3: Item 9 | JB3: Item 10 | JC3: TOTAL
A4: P01 | B4: CONTROL group | C4: 1 | D4: 3 | E4: 1 | F4: 1 | G4: 2 | H4: 2 | I4: 2 | J4: 5 | K4: 5 | L4: 1 | M4: 1 | N4: 1 | O4: 1 | P4: 2 | R4: 3 | S4: 3 | T4: 0 | U4: 4 | V4: 2 | W4: 2 | X4: 3 | Y4: 0 | Z4: 2 | AA4: 3 | AB4: 4 | AC4: 4 | AD4: 4 | AE4: 4 | AF4: 2 | AG4: 0 | AH4: 2 | AI4: 2 | AJ4: 4 | AK4: 4 | AL4: =SUM(R4:AK4) -> 52 | AM4: 4 | AN4: 4 | AO4: 3 | AP4: 4 | AQ4: 2 | AR4: 3 | AS4: 3 | AT4: 4 | AU4: 3 | AV4: 1 | AW4: 3 | AX4: 1 | AY4: 1 | AZ4: 2 | BA4: 2 | BB4: 2 | BC4: 3 | BD4: 1 | BE4: 2 | BF4: 2 | BG4: 1 | BH4: 1 | BI4: 1 | BJ4: 3 | BK4: 1 | BL4: 1 | BM4: 1 | BN4: 2 | BO4: 2 | BP4: 1 | BQ4: 1 | BR4: 2 | BS4: 4 | BT4: 2 | BU4: 1 | BV4: 4 | BW4: 3 | BX4: 1 | BY4: 1 | BZ4: 1 | CA4: =SUM(AM4:BZ4) -> 84 | CB4: =CA4/40 -> 2.1 | CC4: 1 | CD4: 1 | CE4: 1 | CF4: 0 | CG4: 0 | CH4: 0 | CI4: =SUM(CD4:CH4) -> 2 | CJ4: 3 | CK4: 5 | CL4: 2 | CM4: 1 | CN4: 3 | CO4: 3 | CP4: 3 | CQ4: 2 | CR4: 1 | CS4: 2 | CT4: 1 | CU4: 1 | CV4: 1 | CW4: 2 | CX4: =SUM(CJ4:CW4) -> 30 | CY4: 2 | CZ4: 1 | DA4: 0 | DB4: 0 | DC4: 0 | DD4: 2 | DE4: 2 | DF4: 2 | DG4: 2 | DH4: 1 | DI4: =SUM(CY4:DH4) -> 12 | DJ4: 2 | DK4: 2 | DL4: 1 | DM4: 1 | DN4: 1 | DO4: 1 | DP4: =SUM(DJ4:DO4) -> 8 | DQ4: =DP4/6 -> 1.3333333 | DR4: 1 | DS4: 1 | DT4: 1 | DU4: 1 | DV4: 1 | DW4: 2 | DX4: 1 | DY4: 2 | DZ4: 1 | EA4: 1 | EB4: =SUM(DR4:EA4) -> 12 | ED4: 2,3 | EE4: 1,2 | EF4: 1 | EG4: 1,2 | EH4: 1 | EI4: 3 | EJ4: 3 | EK4: 2 | EL4: 2 | EM4: 1 | EN4: 1 | EO4: 1 | EP4: 1 | EQ4: 1 | ES4: 2 | ET4: 2 | EU4: 1 | EV4: 3 | EW4: 2 | EX4: 3 | EY4: 3 | EZ4: 3 | FA4: 2 | FB4: 3 | FC4: 2 | FD4: 4 | FE4: 4 | FF4: 4 | FG4: 2 | FH4: 0 | FI4: 2 | FJ4: 2 | FK4: 2 | FL4: 0 | FM4: =SUM(ES4:FL4) -> 46 | FN4: 3 | FO4: 2 | FP4: 2 | FQ4: 3 | FR4: 3 | FS4: 2 | FT4: 3 | FU4: 1 | FV4: 3 | FW4: 2 | FX4: 3 | FY4: 1 | FZ4: 1 | GA4: 2 | GB4: 3 | GC4: 3 | GD4: 2 | GE4: 2 | GF4: 3 | GG4: 3 | GH4: 4 | GI4: 4 | GJ4: 4 | GK4: 3 | GL4: 2 | GM4: 3 | GN4: 1 | GO4: 2 | GP4: 2 | GQ4: 1 | GR4: 3 | GS4: 3 | GT4: 4 | GU4: 3 | GV4: 4 | GW4: 4 | GX4: 3 | GY4: 4 | GZ4: 1 | HA4: 1 | HB4: =SUM(FN4:HA4) -> 103 | HC4: =HB4/40 -> 2.575 | HD4: 1 | HE4: 1 | HF4: 1 | HG4: 1 | HH4: 1 | HI4: 0 | HJ4: =SUM(HE4:HI4) -> 4 | HK4: 5 | HL4: 5 | HM4: 3 | HN4: 2 | HO4: 2 | HP4: 2 | HQ4: 2 | HR4: 2 | HS4: 2 | HT4: 2 | HU4: 2 | HV4: 1 | HW4: 1 | HX4: 1 | HY4: =SUM(HK4:HX4) -> 32 | HZ4: 2 | IA4: 2 | IB4: 2 | IC4: 0 | ID4: 0 | IE4: 1 | IF4: 0 | IG4: 0 | IH4: 0 | II4: 1 | IJ4: =SUM(HZ4:II4) -> 8 | IK4: 1 | IL4: 1 | IM4: 1 | IN4: 1 | IO4: 1 | IP4: 1 | IQ4: =SUM(IK4:IP4) -> 6 | IR4: =IQ4/6 -> 1 | IS4: 1 | IT4: 1 | IU4: 1 | IV4: 2 | IW4: 1 | IX4: 1 | IY4: 1 | IZ4: 1 | JA4: 2 | JB4: 1 | JC4: =SUM(IS4:JB4) -> 12
A5: P02 | C5: 2 | D5: 3 | E5: 3 | F5: 1 | G5: 4 | H5: 3 | I5: 3 | J5: 3 | K5: 5 | L5: 1 | M5: 5 | N5: 1 | O5: 1 | P5: 2 | R5: 0 | S5: 1 | T5: 0 | U5: 1 | V5: 2 | W5: 2 | X5: 0 | Y5: 0 | Z5: 0 | AA5: 0 | AB5: 0 | AC5: 0 | AD5: 0 | AE5: 0 | AF5: 0 | AG5: 0 | AH5: 0 | AI5: 0 | AJ5: 0 | AK5: 0 | AL5: =SUM(R5:AK5) -> 6 | AM5: 2 | AN5: 1 | AO5: 2 | AP5: 1 | AQ5: 1 | AR5: 1 | AS5: 1 | AT5: 1 | AU5: 1 | AV5: 1 | AW5: 1 | AX5: 3 | AY5: 2 | AZ5: 1 | BA5: 3 | BB5: 1 | BC5: 1 | BD5: 1 | BE5: 1 | BF5: 1 | BG5: 1 | BH5: 2 | BI5: 1 | BJ5: 1 | BK5: 1 | BL5: 1 | BM5: 1 | BN5: 1 | BO5: 1 | BP5: 1 | BQ5: 1 | BR5: 1 | BS5: 1 | BT5: 1 | BU5: 1 | BV5: 1 | BW5: 1 | BX5: 1 | BY5: 1 | BZ5: 1 | CA5: =SUM(AM5:BZ5) -> 48 | CB5: =CA5/40 -> 1.2 | CC5: 1 | CD5: 1 | CE5: 0 | CF5: 0 | CG5: 0 | CH5: 0 | CI5: =SUM(CD5:CH5) -> 1 | CJ5: 5 | CK5: 5 | CL5: 4 | CM5: 5 | CN5: 1 | CO5: 3 | CP5: 3 | CQ5: 4 | CR5: 4 | CS5: 4 | CT5: 4 | CU5: 5 | CV5: 5 | CW5: 5 | CX5: =SUM(CJ5:CW5) -> 57 | CY5: 1 | CZ5: 4 | DA5: 3 | DB5: 3 | DC5: 4 | DD5: 4 | DE5: 4 | DF5: 4 | DG5: 4 | DH5: 4 | DI5: =SUM(CY5:DH5) -> 35 | DJ5: 5 | DK5: 5 | DL5: 4 | DM5: 5 | DN5: 5 | DO5: 5 | DP5: =SUM(DJ5:DO5) -> 29 | DQ5: =DP5/6 -> 4.8333333 | DR5: 4 | DS5: 2 | DT5: 3 | DU5: 3 | DV5: 3 | DW5: 3 | DX5: 3 | DY5: 3 | DZ5: 3 | EA5: 3 | EB5: =SUM(DR5:EA5) -> 30 | ED5: 5 | EE5: 2 | EF5: 3 | EG5: 2 | EH5: 5 | EI5: 5 | EJ5: 3 | EK5: 2,3 | EL5: 3,4 | EM5: 1 | EN5: 5 | EO5: 1 | EP5: 1 | EQ5: 5 | ES5: 1 | ET5: 1 | EU5: 0 | EV5: 1 | EW5: 2 | EX5: 0 | EY5: 0 | EZ5: 0 | FA5: 0 | FB5: 0 | FC5: 0 | FD5: 0 | FE5: 0 | FF5: 0 | FG5: 0 | FH5: 0 | FI5: 0 | FJ5: 0 | FK5: 0 | FL5: 0 | FM5: =SUM(ES5:FL5) -> 5 | FN5: 1 | FO5: 1 | FP5: 2 | FQ5: 1 | FR5: 1 | FS5: 2 | FT5: 1 | FU5: 1 | FV5: 1 | FW5: 1 | FX5: 1 | FY5: 1 | FZ5: 1 | GA5: 1 | GB5: 3 | GC5: 1 | GD5: 1 | GE5: 1 | GF5: 1 | GG5: 2 | GH5: 2 | GI5: 2 | GJ5: 1 | GK5: 1 | GL5: 1 | GM5: 1 | GN5: 1 | GO5: 1 | GP5: 1 | GQ5: 1 | GR5: 1 | GS5: 1 | GT5: 1 | GU5: 1 | GV5: 1 | GW5: 1 | GX5: 1 | GY5: 1 | GZ5: 1 | HA5: 1 | HB5: =SUM(FN5:HA5) -> 47 | HC5: =HB5/40 -> 1.175 | HD5: 1 | HE5: 0 | HF5: 0 | HG5: 0 | HH5: 0 | HI5: 0 | HJ5: =SUM(HE5:HI5) -> 0 | HK5: 4 | HL5: 4 | HM5: 4 | HN5: 4 | HO5: 4 | HP5: 4 | HQ5: 4 | HR5: 4 | HS5: 4 | HT5: 4 | HU5: 4 | HV5: 4 | HW5: 4 | HX5: 4 | HY5: =SUM(HK5:HX5) -> 56 | HZ5: 2 | IA5: 3 | IB5: 3 | IC5: 3 | ID5: 2 | IE5: 3 | IF5: 3 | IG5: 3 | IH5: 2 | II5: 3 | IJ5: =SUM(HZ5:II5) -> 27 | IK5: 5 | IL5: 5 | IM5: 5 | IN5: 2 | IO5: 5 | IP5: 4 | IQ5: =SUM(IK5:IP5) -> 26 | IR5: =IQ5/6 -> 4.3333333 | IS5: 4 | IT5: 3 | IU5: 3 | IV5: 3 | IW5: 3 | IX5: 2 | IY5: 2 | IZ5: 2 | JA5: 3 | JB5: 2 | JC5: =SUM(IS5:JB5) -> 27
A6: P03 | C6: 5 | D6: 1,3 | E6: 1,3 | F6: 1,3 | G6: 1,3 | H6: 1,3 | I6: 5 | J6: 5 | K6: 5 | L6: 1,3 | M6: 1 | N6: 1,3 | O6: 1,3 | P6: 1,3 | R6: 4 | S6: 4 | T6: 2 | U6: 4 | V6: 4 | W6: 4 | X6: 4 | Y6: 4 | Z6: 4 | AA6: 4 | AB6: 4 | AC6: 4 | AD6: 4 | AE6: 4 | AF6: 2 | AG6: 1 | AH6: 4 | AI6: 4 | AJ6: 3 | AK6: 3 | AL6: =SUM(R6:AK6) -> 71 | AM6: 3 | AN6: 2 | AO6: 4 | AP6: 4 | AQ6: 4 | AR6: 4 | AS6: 4 | AT6: 3 | AU6: 3 | AV6: 1 | AW6: 4 | AX6: 3 | AY6: 3 | AZ6: 4 | BA6: 4 | BB6: 4 | BC6: 4 | BD6: 4 | BE6: 4 | BF6: 4 | BG6: 4 | BH6: 3 | BI6: 3 | BJ6: 4 | BK6: 1 | BL6: 4 | BM6: 3 | BN6: 3 | BO6: 3 | BP6: 3 | BQ6: 3 | BR6: 3 | BS6: 3 | BT6: 4 | BU6: 4 | BV6: 3 | BW6: 4 | BX6: 4 | BY6: 3 | BZ6: 1 | CA6: =SUM(AM6:BZ6) -> 133 | CB6: =CA6/40 -> 3.325 | CC6: 1 | CD6: 1 | CE6: 1 | CF6: 1 | CG6: 1 | CH6: 1 | CI6: =SUM(CD6:CH6) -> 5 | CJ6: 2 | CK6: 3 | CL6: 1 | CM6: 2 | CN6: 5 | CO6: 4 | CP6: 2 | CQ6: 2 | CR6: 2 | CS6: 2 | CT6: 2 | CU6: 1 | CV6: 1 | CW6: 1 | CX6: =SUM(CJ6:CW6) -> 30 | CY6: 0 | CZ6: 2 | DA6: 2 | DB6: 0 | DC6: 0 | DD6: 0 | DE6: 0 | DF6: 0 | DG6: 0 | DH6: 0 | DI6: =SUM(CY6:DH6) -> 4 | DJ6: 1 | DK6: 1 | DL6: 1 | DM6: 1 | DN6: 1 | DO6: 1 | DP6: =SUM(DJ6:DO6) -> 6 | DQ6: =DP6/6 -> 1 | DR6: 1 | DS6: 1 | DT6: 1 | DU6: 1 | DV6: 1 | DW6: 1 | DX6: 1 | DY6: 1 | DZ6: 1 | EA6: 1 | EB6: =SUM(DR6:EA6) -> 10 | ED6: 2,3 | EE6: 1,3 | EF6: 3 | EG6: 3 | EH6: 1 | EI6: 3 | EJ6: 2,3 | EK6: 3 | EL6: 3 | EM6: 1,3 | EN6: 1 | EO6: 1 | EP6: 1 | EQ6: 3 | ES6: 3 | ET6: 4 | EU6: 3 | EV6: 4 | EW6: 3 | EX6: 2 | EY6: 3 | EZ6: 0 | FA6: 1 | FB6: 0 | FC6: 3 | FD6: 2 | FE6: 2 | FF6: 2 | FG6: 0 | FH6: 0 | FI6: 3 | FJ6: 3 | FK6: 3 | FL6: 4 | FM6: =SUM(ES6:FL6) -> 45 | FN6: 2 | FO6: 3 | FP6: 3 | FQ6: 3 | FR6: 2 | FS6: 3 | FT6: 2 | FU6: 4 | FV6: 3 | FW6: 1 | FX6: 1 | FY6: 2 | FZ6: 3 | GA6: 3 | GB6: 2 | GC6: 3 | GD6: 3 | GE6: 1 | GF6: 3 | GG6: 1 | GH6: 1 | GI6: 3 | GJ6: 3 | GK6: 2 | GL6: 1 | GM6: 3 | GN6: 1 | GO6: 1 | GP6: 2 | GQ6: 1 | GR6: 2 | GS6: 1 | GT6: 2 | GU6: 2 | GV6: 3 | GW6: 2 | GX6: 3 | GY6: 3 | GZ6: 1 | HA6: 1 | HB6: =SUM(FN6:HA6) -> 86 | HC6: =HB6/40 -> 2.15 | HD6: 1 | HE6: 0 | HF6: 0 | HG6: 1 | HH6: 1 | HI6: 1 | HJ6: =SUM(HE6:HI6) -> 3 | HK6: 1 | HL6: 1 | HM6: 1 | HN6: 1 | HO6: 3 | HP6: 2 | HQ6: 2 | HR6: 1 | HS6: 2 | HT6: 3 | HU6: 1 | HV6: 2 | HW6: 1 | HX6: 2 | HY6: =SUM(HK6:HX6) -> 23 | HZ6: 0 | IA6: 2 | IB6: 2 | IC6: 0 | ID6: 0 | IE6: 2 | IF6: 0 | IG6: 3 | IH6: 0 | II6: 0 | IJ6: =SUM(HZ6:II6) -> 9 | IK6: 1 | IL6: 1 | IM6: 1 | IN6: 1 | IO6: 1 | IP6: 1 | IQ6: =SUM(IK6:IP6) -> 6 | IR6: =IQ6/6 -> 1 | IS6: 1 | IT6: 1 | IU6: 1 | IV6: 1 | IW6: 1 | IX6: 1 | IY6: 1 | IZ6: 3 | JA6: 1 | JB6: 1 | JC6: =SUM(IS6:JB6) -> 12
A7: P04 | C7: 3 | D7: 1 | E7: 1 | F7: 1 | G7: 3 | H7: 3 | I7: 2 | J7: 4 | K7: 5 | L7: 1 | M7: 5 | N7: 1 | O7: 1 | P7: 3 | R7: 2 | S7: 2 | T7: 1 | U7: 2 | V7: 1 | W7: 2 | X7: 2 | Y7: 0 | Z7: 0 | AA7: 0 | AB7: 2 | AC7: 1 | AD7: 0 | AE7: 0 | AF7: 1 | AG7: 0 | AH7: 1 | AI7: 1 | AJ7: 1 | AK7: 1 | AL7: =SUM(R7:AK7) -> 20 | AM7: 3 | AN7: 2 | AO7: 3 | AP7: 1 | AQ7: 2 | AR7: 2 | AS7: 2 | AT7: 3 | AU7: 4 | AV7: 1 | AW7: 1 | AX7: 3 | AY7: 1 | AZ7: 3 | BA7: 1 | BB7: 1 | BC7: 2 | BD7: 1 | BE7: 2 | BF7: 1 | BG7: 1 | BH7: 1 | BI7: 1 | BJ7: 1 | BK7: 1 | BL7: 2 | BM7: 1 | BN7: 1 | BO7: 1 | BP7: 1 | BQ7: 1 | BR7: 1 | BS7: 1 | BT7: 3 | BU7: 3 | BV7: 1 | BW7: 1 | BX7: 3 | BY7: 2 | BZ7: 1 | CA7: =SUM(AM7:BZ7) -> 67 | CB7: =CA7/40 -> 1.675 | CC7: 1 | CD7: 1 | CE7: 1 | CF7: 1 | CG7: 1 | CH7: 1 | CI7: =SUM(CD7:CH7) -> 5 | CJ7: 5 | CK7: 4 | CL7: 1 | CM7: 5 | CN7: 2 | CO7: 3 | CP7: 3 | CQ7: 1 | CR7: 4 | CS7: 3 | CT7: 3 | CU7: 4 | CV7: 4 | CW7: 2 | CX7: =SUM(CJ7:CW7) -> 44 | CY7: 2 | CZ7: 2 | DA7: 3 | DB7: 1 | DC7: 1 | DD7: 4 | DE7: 4 | DF7: 4 | DG7: 1 | DH7: 3 | DI7: =SUM(CY7:DH7) -> 25 | DJ7: 4 | DK7: 4 | DL7: 4 | DM7: 1 | DN7: 1 | DO7: 1 | DP7: =SUM(DJ7:DO7) -> 15 | DQ7: =DP7/6 -> 2.5 | DR7: 3 | DS7: 1 | DT7: 2 | DU7: 2 | DV7: 1 | DW7: 2 | DX7: 1 | DY7: 2 | DZ7: 3 | EA7: 1 | EB7: =SUM(DR7:EA7) -> 18 | ED7: 3 | EE7: 3 | EF7: 3 | EG7: 1,2 | EH7: 1,2,3 | EI7: 3 | EJ7: 2 | EK7: 2 | EL7: 2,3 | EM7: 1 | EN7: 1 | EO7: 1 | EP7: 1,2,3 | EQ7: 2 | ES7: 3 | ET7: 2 | EU7: 2 | EV7: 3 | EW7: 3 | EX7: 3 | EY7: 3 | EZ7: 2 | FA7: 0 | FB7: 0 | FC7: 2 | FD7: 2 | FE7: 0 | FF7: 1 | FG7: 0 | FH7: 0 | FI7: 2 | FJ7: 2 | FK7: 1 | FL7: 2 | FM7: =SUM(ES7:FL7) -> 33 | FN7: 3 | FO7: 3 | FP7: 3 | FQ7: 1 | FR7: 1 | FS7: 2 | FT7: 2 | FU7: 2 | FV7: 2 | FW7: 2 | FX7: 3 | FY7: 1 | FZ7: 2 | GA7: 1 | GB7: 1 | GC7: 3 | GD7: 2 | GE7: 2 | GF7: 2 | GG7: 2 | GH7: 2 | GI7: 1 | GJ7: 1 | GK7: 1 | GL7: 1 | GM7: 2 | GN7: 1 | GO7: 1 | GP7: 1 | GQ7: 1 | GR7: 1 | GS7: 1 | GT7: 3 | GU7: 3 | GV7: 3 | GW7: 1 | GX7: 2 | GY7: 3 | GZ7: 2 | HA7: 1 | HB7: =SUM(FN7:HA7) -> 72 | HC7: =HB7/40 -> 1.8 | HD7: 1 | HE7: 1 | HF7: 1 | HG7: 1 | HH7: 1 | HI7: 0 | HJ7: =SUM(HE7:HI7) -> 4 | HK7: 3 | HL7: 3 | HM7: 2 | HN7: 4 | HO7: 2 | HP7: 2 | HQ7: 2 | HR7: 2 | HS7: 3 | HT7: 3 | HU7: 2 | HV7: 2 | HW7: 1 | HX7: 2 | HY7: =SUM(HK7:HX7) -> 33 | HZ7: 2 | IA7: 2 | IB7: 2 | IC7: 2 | ID7: 2 | IE7: 2 | IF7: 2 | IG7: 2 | IH7: 0 | II7: 0 | IJ7: =SUM(HZ7:II7) -> 16 | IK7: 5 | IL7: 5 | IM7: 4 | IN7: 1 | IO7: 4 | IP7: 2 | IQ7: =SUM(IK7:IP7) -> 21 | IR7: =IQ7/6 -> 3.5 | IS7: 2 | IT7: 2 | IU7: 2 | IV7: 2 | IW7: 2 | IX7: 2 | IY7: 2 | IZ7: 2 | JA7: 2 | JB7: 3 | JC7: =SUM(IS7:JB7) -> 21
A8: P05 | C8: 2 | D8: 3 | E8: 3 | F8: 2 | G8: 3 | H8: 3 | I8: 2 | J8: 2 | K8: 3 | L8: 1 | M8: 1 | N8: 1 | O8: 1 | P8: 3 | R8: 0 | S8: 1 | T8: 1 | U8: 1 | V8: 0 | W8: 0 | X8: 0 | Y8: 1 | Z8: 0 | AA8: 0 | AB8: 0 | AC8: 1 | AD8: 0 | AE8: 0 | AF8: 0 | AG8: 0 | AH8: 0 | AI8: 0 | AJ8: 0 | AK8: 0 | AL8: =SUM(R8:AK8) -> 5 | AM8: 2 | AN8: 1 | AO8: 1 | AP8: 1 | AQ8: 1 | AR8: 2 | AS8: 1 | AT8: 1 | AU8: 1 | AV8: 2 | AW8: 2 | AX8: 1 | AY8: 1 | AZ8: 1 | BA8: 1 | BB8: 2 | BC8: 1 | BD8: 3 | BE8: 1 | BF8: 1 | BG8: 1 | BH8: 1 | BI8: 1 | BJ8: 1 | BK8: 1 | BL8: 1 | BM8: 1 | BN8: 1 | BO8: 1 | BP8: 1 | BQ8: 1 | BR8: 1 | BS8: 1 | BT8: 1 | BU8: 4 | BV8: 2 | BW8: 1 | BX8: 1 | BY8: 1 | BZ8: 1 | CA8: =SUM(AM8:BZ8) -> 51 | CB8: =CA8/40 -> 1.275 | CC8: 1 | CD8: 0 | CE8: 0 | CF8: 0 | CG8: 1 | CH8: 0 | CI8: =SUM(CD8:CH8) -> 1 | CJ8: 4 | CK8: 5 | CL8: 4 | CM8: 4 | CN8: 2 | CO8: 3 | CP8: 2 | CQ8: 2 | CR8: 3 | CS8: 3 | CT8: 2 | CU8: 3 | CV8: 1 | CW8: 2 | CX8: =SUM(CJ8:CW8) -> 40 | CY8: 1 | CZ8: 1 | DA8: 2 | DB8: 0 | DC8: 1 | DD8: 2 | DE8: 2 | DF8: 2 | DG8: 1 | DH8: 0 | DI8: =SUM(CY8:DH8) -> 12 | DJ8: 4 | DK8: 4 | DL8: 2 | DM8: 4 | DN8: 4 | DO8: 2 | DP8: =SUM(DJ8:DO8) -> 20 | DQ8: =DP8/6 -> 3.3333333 | DR8: 2 | DS8: 2 | DT8: 3 | DU8: 1 | DV8: 3 | DW8: 2 | DX8: 1 | DY8: 3 | DZ8: 3 | EA8: 2 | EB8: =SUM(DR8:EA8) -> 22 | ED8: 2,3 | EE8: 2,3 | EF8: 1 | EG8: 1 | EH8: 1 | EI8: 5 | EJ8: 5 | EK8: 2 | EL8: 3 | EM8: 1 | EN8: 1 | EO8: 1 | EP8: 1 | EQ8: 3 | ES8: 1 | ET8: 0 | EU8: 0 | EV8: 0 | EW8: 0 | EX8: 0 | EY8: 0 | EZ8: 0 | FA8: 0 | FB8: 2 | FC8: 0 | FD8: 0 | FE8: 0 | FF8: 0 | FG8: 0 | FH8: 0 | FI8: 0 | FJ8: 0 | FK8: 0 | FL8: 0 | FM8: =SUM(ES8:FL8) -> 3 | FN8: 2 | FO8: 1 | FP8: 1 | FQ8: 1 | FR8: 1 | FS8: 1 | FT8: 1 | FU8: 1 | FV8: 1 | FW8: 1 | FX8: 1 | FY8: 1 | FZ8: 1 | GA8: 1 | GB8: 1 | GC8: 1 | GD8: 2 | GE8: 1 | GF8: 1 | GG8: 1 | GH8: 1 | GI8: 1 | GJ8: 1 | GK8: 1 | GL8: 1 | GM8: 1 | GN8: 1 | GO8: 1 | GP8: 1 | GQ8: 1 | GR8: 1 | GS8: 1 | GT8: 3 | GU8: 2 | GV8: 2 | GW8: 1 | GX8: 1 | GY8: 2 | GZ8: 1 | HA8: 1 | HB8: =SUM(FN8:HA8) -> 47 | HC8: =HB8/40 -> 1.175 | HD8: 1 | HE8: 0 | HF8: 0 | HG8: 0 | HH8: 0 | HI8: 0 | HJ8: =SUM(HE8:HI8) -> 0 | HK8: 2 | HL8: 2 | HM8: 3 | HN8: 4 | HO8: 2 | HP8: 3 | HQ8: 3 | HR8: 3 | HS8: 3 | HT8: 3 | HU8: 2 | HV8: 3 | HW8: 2 | HX8: 3 | HY8: =SUM(HK8:HX8) -> 38 | HZ8: 2 | IA8: 2 | IB8: 2 | IC8: 2 | ID8: 2 | IE8: 1 | IF8: 1 | IG8: 1 | IH8: 2 | II8: 2 | IJ8: =SUM(HZ8:II8) -> 17 | IK8: 4 | IL8: 2 | IM8: 4 | IN8: 4 | IO8: 2 | IP8: 2 | IQ8: =SUM(IK8:IP8) -> 18 | IR8: =IQ8/6 -> 3 | IS8: 2 | IT8: 2 | IU8: 3 | IV8: 3 | IW8: 2 | IX8: 2 | IY8: 2 | IZ8: 2 | JA8: 2 | JB8: 2 | JC8: =SUM(IS8:JB8) -> 22
A9: P06 | C9: 5 | D9: 3 | E9: 3 | F9: 2 | G9: 5 | H9: 5 | I9: 2 | J9: 1 | K9: 3 | L9: 2 | M9: 2 | N9: 1 | O9: 1 | P9: 3 | R9: 1 | S9: 3 | T9: 3 | U9: 3 | V9: 2 | W9: 2 | X9: 2 | Y9: 0 | Z9: 0 | AA9: 0 | AB9: 0 | AC9: 2 | AD9: 2 | AE9: 1 | AF9: 0 | AG9: 0 | AH9: 3 | AI9: 3 | AJ9: 2 | AK9: 4 | AL9: =SUM(R9:AK9) -> 33 | AM9: 4 | AN9: 2 | AO9: 3 | AP9: 2 | AQ9: 3 | AR9: 3 | AS9: 3 | AT9: 4 | AU9: 4 | AV9: 1 | AW9: 2 | AX9: 3 | AY9: 3 | AZ9: 2 | BA9: 2 | BB9: 3 | BC9: 2 | BD9: 2 | BE9: 2 | BF9: 2 | BG9: 2 | BH9: 1 | BI9: 1 | BJ9: 2 | BK9: 2 | BL9: 2 | BM9: 1 | BN9: 1 | BO9: 2 | BP9: 2 | BQ9: 4 | BR9: 2 | BS9: 1 | BT9: 2 | BU9: 2 | BV9: 2 | BW9: 1 | BX9: 2 | BY9: 2 | BZ9: 1 | CA9: =SUM(AM9:BZ9) -> 87 | CB9: =CA9/40 -> 2.175 | CC9: 1 | CD9: 1 | CE9: 1 | CF9: 1 | CG9: 1 | CH9: 0 | CI9: =SUM(CD9:CH9) -> 4 | CJ9: 2 | CK9: 3 | CL9: 3 | CM9: 2 | CN9: 3 | CO9: 5 | CP9: 4 | CQ9: 3 | CR9: 3 | CS9: 2 | CT9: 3 | CU9: 5 | CV9: 2 | CW9: 3 | CX9: =SUM(CJ9:CW9) -> 43 | CY9: 2 | CZ9: 2 | DA9: 4 | DB9: 1 | DC9: 2 | DD9: 1 | DE9: 2 | DF9: 2 | DG9: 1 | DH9: 2 | DI9: =SUM(CY9:DH9) -> 19 | DJ9: 4 | DK9: 2 | DL9: 2 | DM9: 4 | DN9: 2 | DO9: 4 | DP9: =SUM(DJ9:DO9) -> 18 | DQ9: =DP9/6 -> 3 | DR9: 3 | DS9: 1 | DT9: 1 | DU9: 3 | DV9: 1 | DW9: 3 | DX9: 2 | DY9: 2 | DZ9: 3 | EA9: 3 | EB9: =SUM(DR9:EA9) -> 22 | ED9: 5 | EE9: 2,3 | EF9: 2,3 | EG9: 2,3 | EH9: 2,3 | EI9: 2,3 | EJ9: 3 | EK9: 1,2,3 | EL9: 1 | EM9: 1 | EN9: 1 | EO9: 1 | EP9: 1 | EQ9: 2 | ES9: 1 | ET9: 3 | EU9: 3 | EV9: 1 | EW9: 0 | EX9: 3 | EY9: 3 | EZ9: 2 | FA9: 1 | FB9: 1 | FC9: 3 | FD9: 3 | FE9: 3 | FF9: 1 | FG9: 0 | FH9: 1 | FI9: 1 | FJ9: 2 | FK9: 3 | FL9: 4 | FM9: =SUM(ES9:FL9) -> 39 | FN9: 3 | FO9: 2 | FP9: 2 | FQ9: 2 | FR9: 3 | FS9: 3 | FT9: 2 | FU9: 4 | FV9: 4 | FW9: 2 | FX9: 3 | FY9: 1 | FZ9: 2 | GA9: 2 | GB9: 2 | GC9: 2 | GD9: 3 | GE9: 2 | GF9: 3 | GG9: 2 | GH9: 2 | GI9: 1 | GJ9: 1 | GK9: 3 | GL9: 3 | GM9: 3 | GN9: 1 | GO9: 1 | GP9: 2 | GQ9: 2 | GR9: 3 | GS9: 2 | GT9: 2 | GU9: 2 | GV9: 2 | GW9: 2 | GX9: 2 | GY9: 3 | GZ9: 2 | HA9: 1 | HB9: =SUM(FN9:HA9) -> 89 | HC9: =HB9/40 -> 2.225 | HD9: 1 | HE9: 1 | HF9: 1 | HG9: 1 | HH9: 1 | HI9: 0 | HJ9: =SUM(HE9:HI9) -> 4 | HK9: 4 | HL9: 3 | HM9: 4 | HN9: 4 | HO9: 4 | HP9: 3 | HQ9: 3 | HR9: 2 | HS9: 4 | HT9: 4 | HU9: 3 | HV9: 3 | HW9: 2 | HX9: 2 | HY9: =SUM(HK9:HX9) -> 45 | HZ9: 1 | IA9: 2 | IB9: 2 | IC9: 2 | ID9: 2 | IE9: 2 | IF9: 2 | IG9: 2 | IH9: 1 | II9: 2 | IJ9: =SUM(HZ9:II9) -> 18 | IK9: 4 | IL9: 2 | IM9: 4 | IN9: 2 | IO9: 4 | IP9: 2 | IQ9: =SUM(IK9:IP9) -> 18 | IR9: =IQ9/6 -> 3 | IS9: 2 | IT9: 2 | IU9: 3 | IV9: 2 | IW9: 3 | IX9: 2 | IY9: 2 | IZ9: 3 | JA9: 3 | JB9: 2 | JC9: =SUM(IS9:JB9) -> 24
A10: P07 | C10: 2,3 | D10: 1 | E10: 1 | F10: 1 | G10: 1 | H10: 3 | I10: 5 | J10: 2 | K10: 5 | L10: 1 | M10: 1 | N10: 1 | O10: 1 | P10: 1 | R10: 4 | S10: 0 | T10: 0 | U10: 3 | V10: 4 | W10: 3 | X10: 3 | Y10: 0 | Z10: 4 | AA10: 4 | AB10: 4 | AC10: 4 | AD10: 4 | AE10: 4 | AF10: 1 | AG10: 3 | AH10: 4 | AI10: 4 | AJ10: 4 | AK10: 4 | AL10: =SUM(R10:AK10) -> 61 | AM10: 1 | AN10: 2 | AO10: 3 | AP10: 4 | AQ10: 4 | AR10: 4 | AS10: 4 | AT10: 4 | AU10: 4 | AV10: 3 | AW10: 3 | AX10: 1 | AY10: 3 | AZ10: 4 | BA10: 3 | BB10: 4 | BC10: 4 | BD10: 3 | BE10: 3 | BF10: 4 | BG10: 4 | BH10: 3 | BI10: 1 | BJ10: 4 | BK10: 3 | BL10: 2 | BM10: 4 | BN10: 2 | BO10: 1 | BP10: 1 | BQ10: 1 | BR10: 3 | BS10: 4 | BT10: 4 | BU10: 3 | BV10: 4 | BW10: 1 | BX10: 1 | BY10: 1 | BZ10: 1 | CA10: =SUM(AM10:BZ10) -> 113 | CB10: =CA10/40 -> 2.825 | CC10: 1 | CD10: 0 | CE10: 1 | CF10: 1 | CG10: 1 | CH10: 1 | CI10: =SUM(CD10:CH10) -> 4 | CJ10: 3 | CK10: 1 | CL10: 2 | CM10: 1 | CN10: 2 | CO10: 2 | CP10: 2 | CQ10: 3 | CR10: 1 | CS10: 4 | CT10: 1 | CU10: 1 | CV10: 3 | CW10: 4 | CX10: =SUM(CJ10:CW10) -> 30 | CY10: 2 | CZ10: 4 | DA10: 0 | DB10: 3 | DC10: 1 | DD10: 3 | DE10: 2 | DF10: 2 | DG10: 1 | DH10: 4 | DI10: =SUM(CY10:DH10) -> 22 | DJ10: 4 | DK10: 1 | DL10: 5 | DM10: 2 | DN10: 1 | DO10: 1 | DP10: =SUM(DJ10:DO10) -> 14 | DQ10: =DP10/6 -> 2.3333333 | DR10: 3 | DS10: 1 | DT10: 4 | DU10: 4 | DV10: 1 | DW10: 3 | DX10: 1 | DY10: 3 | DZ10: 4 | EA10: 1 | EB10: =SUM(DR10:EA10) -> 25 | ED10: 5 | EE10: 3 | EF10: 3 | EG10: 3 | EH10: 3 | EI10: 1 | EJ10: 5 | EK10: 2 | EL10: 2 | EM10: 1 | EN10: 1 | EO10: 1 | EP10: 1 | EQ10: 2 | ES10: 4 | ET10: 3 | EU10: 3 | EV10: 3 | EW10: 4 | EX10: 1 | EY10: 3 | EZ10: 0 | FA10: 3 | FB10: 2 | FC10: 3 | FD10: 2 | FE10: 3 | FF10: 3 | FG10: 3 | FH10: 0 | FI10: 3 | FJ10: 3 | FK10: 3 | FL10: 4 | FM10: =SUM(ES10:FL10) -> 53 | FN10: 3 | FO10: 3 | FP10: 3 | FQ10: 3 | FR10: 4 | FS10: 3 | FT10: 3 | FU10: 4 | FV10: 4 | FW10: 1 | FX10: 4 | FY10: 1 | FZ10: 3 | GA10: 3 | GB10: 2 | GC10: 3 | GD10: 3 | GE10: 3 | GF10: 3 | GG10: 3 | GH10: 3 | GI10: 2 | GJ10: 2 | GK10: 3 | GL10: 3 | GM10: 2 | GN10: 2 | GO10: 2 | GP10: 3 | GQ10: 1 | GR10: 2 | GS10: 3 | GT10: 4 | GU10: 3 | GV10: 2 | GW10: 3 | GX10: 2 | GY10: 3 | GZ10: 3 | HA10: 1 | HB10: =SUM(FN10:HA10) -> 108 | HC10: =HB10/40 -> 2.7 | HD10: 1 | HE10: 1 | HF10: 1 | HG10: 1 | HH10: 1 | HI10: 1 | HJ10: =SUM(HE10:HI10) -> 5 | HK10: 2 | HL10: 2 | HM10: 1 | HN10: 1 | HO10: 5 | HP10: 2 | HQ10: 3 | HR10: 1 | HS10: 1 | HT10: 2 | HU10: 1 | HV10: 1 | HW10: 1 | HX10: 2 | HY10: =SUM(HK10:HX10) -> 25 | HZ10: 2 | IA10: 2 | IB10: 2 | IC10: 2 | ID10: 2 | IE10: 2 | IF10: 2 | IG10: 2 | IH10: 1 | II10: 2 | IJ10: =SUM(HZ10:II10) -> 19 | IK10: 4 | IL10: 2 | IM10: 2 | IN10: 1 | IO10: 1 | IP10: 1 | IQ10: =SUM(IK10:IP10) -> 11 | IR10: =IQ10/6 -> 1.8333333 | IS10: 1 | IT10: 2 | IU10: 2 | IV10: 2 | IW10: 1 | IX10: 2 | IY10: 2 | IZ10: 2 | JA10: 2 | JB10: 2 | JC10: =SUM(IS10:JB10) -> 18
A11: P21 | C11: 3 | D11: 3 | E11: 3 | F11: 3 | G11: 5 | H11: 2 | I11: 5 | J11: 5 | K11: 5 | L11: 1 | M11: 1 | N11: 5 | O11: 1 | P11: 3 | R11: 3 | S11: 3 | T11: 3 | U11: 3 | V11: 2 | W11: 3 | X11: 3 | Y11: 1 | Z11: 2 | AA11: 1 | AB11: 2 | AC11: 3 | AD11: 2 | AE11: 2 | AF11: 1 | AG11: 0 | AH11: 1 | AI11: 2 | AJ11: 3 | AK11: 3 | AL11: =SUM(R11:AK11) -> 43 | AM11: 3 | AN11: 2 | AO11: 3 | AP11: 3 | AQ11: 1 | AR11: 3 | AS11: 3 | AT11: 3 | AU11: 3 | AV11: 2 | AW11: 3 | AX11: 2 | AY11: 3 | AZ11: 3 | BA11: 1 | BB11: 3 | BC11: 3 | BD11: 3 | BE11: 3 | BF11: 3 | BG11: 3 | BH11: 3 | BI11: 1 | BJ11: 3 | BK11: 1 | BL11: 3 | BM11: 1 | BN11: 1 | BO11: 4 | BP11: 3 | BQ11: 2 | BR11: 1 | BS11: 2 | BT11: 2 | BU11: 3 | BV11: 2 | BW11: 3 | BX11: 3 | BY11: 1 | BZ11: 2 | CA11: =SUM(AM11:BZ11) -> 97 | CB11: =CA11/40 -> 2.425 | CC11: 1 | CD11: 1 | CE11: 1 | CF11: 1 | CG11: 1 | CH11: 0 | CI11: =SUM(CD11:CH11) -> 4 | CJ11: 2 | CK11: 2 | CL11: 1 | CM11: 2 | CN11: 2 | CO11: 2 | CP11: 2 | CQ11: 2 | CR11: 3 | CS11: 3 | CT11: 2 | CU11: 3 | CV11: 2 | CW11: 2 | CX11: =SUM(CJ11:CW11) -> 30 | CY11: 1 | CZ11: 1 | DA11: 1 | DB11: 1 | DC11: 1 | DD11: 1 | DE11: 1 | DF11: 1 | DG11: 1 | DH11: 1 | DI11: =SUM(CY11:DH11) -> 10 | DJ11: 1 | DK11: 2 | DL11: 1 | DM11: 2 | DN11: 1 | DO11: 2 | DP11: =SUM(DJ11:DO11) -> 9 | DQ11: =DP11/6 -> 1.5 | DR11: 2 | DS11: 2 | DT11: 2 | DU11: 2 | DV11: 2 | DW11: 2 | DX11: 2 | DY11: 2 | DZ11: 2 | EA11: 2 | EB11: =SUM(DR11:EA11) -> 20 | ED11: 3 | EE11: 3 | EF11: 3 | EG11: 3 | EH11: 1 | EI11: 3 | EJ11: 3 | EK11: 3 | EL11: 2 | EM11: 1 | EN11: 3 | EO11: 6 | EP11: 3 | EQ11: 3 | ES11: 3 | ET11: 2 | EU11: 2 | EV11: 2 | EW11: 2 | EX11: 2 | EY11: 2 | EZ11: 2 | FA11: 1 | FB11: 0 | FC11: 2 | FD11: 2 | FE11: 1 | FF11: 1 | FG11: 1 | FH11: 0 | FI11: 1 | FJ11: 2 | FK11: 2 | FL11: 2 | FM11: =SUM(ES11:FL11) -> 32 | FN11: 2 | FO11: 2 | FP11: 3 | FQ11: 2 | FR11: 1 | FS11: 3 | FT11: 2 | FU11: 2 | FV11: 2 | FW11: 2 | FX11: 2 | FY11: 2 | FZ11: 2 | GA11: 3 | GB11: 2 | GC11: 2 | GD11: 2 | GE11: 3 | GF11: 3 | GG11: 3 | GH11: 2 | GI11: 2 | GJ11: 1 | GK11: 2 | GL11: 1 | GM11: 2 | GN11: 1 | GO11: 1 | GP11: 2 | GQ11: 1 | GR11: 1 | GS11: 1 | GT11: 1 | GU11: 1 | GV11: 2 | GW11: 1 | GX11: 2 | GY11: 2 | GZ11: 1 | HA11: 1 | HB11: =SUM(FN11:HA11) -> 73 | HC11: =HB11/40 -> 1.825 | HD11: 1 | HE11: 1 | HF11: 1 | HG11: 0 | HH11: 0 | HI11: 0 | HJ11: =SUM(HE11:HI11) -> 2 | HK11: 2 | HL11: 2 | HM11: 2 | HN11: 3 | HO11: 2 | HP11: 2 | HQ11: 3 | HR11: 2 | HS11: 4 | HT11: 2 | HU11: 2 | HV11: 3 | HW11: 2 | HX11: 3 | HY11: =SUM(HK11:HX11) -> 34 | HZ11: 2 | IA11: 1 | IB11: 1 | IC11: 1 | ID11: 1 | IE11: 1 | IF11: 2 | IG11: 2 | IH11: 1 | II11: 1 | IJ11: =SUM(HZ11:II11) -> 13 | IK11: 2 | IL11: 2 | IM11: 2 | IN11: 2 | IO11: 2 | IP11: 2 | IQ11: =SUM(IK11:IP11) -> 12 | IR11: =IQ11/6 -> 2 | IS11: 2 | IT11: 2 | IU11: 2 | IV11: 2 | IW11: 2 | IX11: 2 | IY11: 1 | IZ11: 1 | JA11: 2 | JB11: 1 | JC11: =SUM(IS11:JB11) -> 17
A12: P29 | C12: 2 | D12: 2 | E12: 2 | F12: 2 | G12: 2 | H12: 3 | I12: 3 | J12: 3 | K12: 5 | L12: 3 | M12: 3 | N12: 6 | O12: 1 | P12: 2 | R12: 2 | S12: 1 | T12: 0 | U12: 1 | V12: 1 | W12: 0 | X12: 0 | Y12: 0 | Z12: 0 | AA12: 1 | AB12: 3 | AC12: 1 | AD12: 0 | AE12: 0 | AF12: 3 | AG12: 0 | AH12: 0 | AI12: 1 | AJ12: 2 | AK12: 3 | AL12: =SUM(R12:AK12) -> 19 | AM12: 2 | AN12: 1 | AO12: 2 | AP12: 1 | AQ12: 1 | AR12: 3 | AS12: 2 | AT12: 3 | AU12: 1 | AV12: 3 | AW12: 1 | AX12: 1 | AY12: 2 | AZ12: 2 | BA12: 2 | BB12: 2 | BC12: 2 | BD12: 2 | BE12: 2 | BF12: 2 | BG12: 1 | BH12: 3 | BI12: 3 | BJ12: 1 | BK12: 1 | BL12: 1 | BM12: 1 | BN12: 1 | BO12: 2 | BP12: 1 | BQ12: 1 | BR12: 1 | BS12: 1 | BT12: 1 | BU12: 2 | BV12: 1 | BW12: 1 | BX12: 2 | BY12: 1 | BZ12: 2 | CA12: =SUM(AM12:BZ12) -> 65 | CB12: =CA12/40 -> 1.625 | CC12: 1 | CD12: 1 | CE12: 0 | CF12: 0 | CG12: 0 | CH12: 0 | CI12: =SUM(CD12:CH12) -> 1 | CJ12: 3 | CK12: 4 | CL12: 3 | CM12: 4 | CN12: 3 | CO12: 3 | CP12: 3 | CQ12: 3 | CR12: 4 | CS12: 3 | CT12: 3 | CU12: 4 | CV12: 3 | CW12: 3 | CX12: =SUM(CJ12:CW12) -> 46 | CY12: 2 | CZ12: 2 | DA12: 2 | DB12: 2 | DC12: 2 | DD12: 1 | DE12: 2 | DF12: 2 | DG12: 2 | DH12: 2 | DI12: =SUM(CY12:DH12) -> 19 | DJ12: 4 | DK12: 4 | DL12: 4 | DM12: 4 | DN12: 4 | DO12: 4 | DP12: =SUM(DJ12:DO12) -> 24 | DQ12: =DP12/6 -> 4 | DR12: 3 | DS12: 3 | DT12: 3 | DU12: 3 | DV12: 2 | DW12: 2 | DX12: 2 | DY12: 2 | DZ12: 2 | EA12: 2 | EB12: =SUM(DR12:EA12) -> 24 | ED12: 3 | EE12: 3 | EF12: 3 | EG12: 3 | EH12: 3 | EI12: 2 | EJ12: 2 | EK12: 2 | EL12: 5 | EM12: 1 | EN12: 3 | EO12: 6 | EP12: 1 | EQ12: 3 | ES12: 1 | ET12: 0 | EU12: 0 | EV12: 0 | EW12: 0 | EX12: 0 | EY12: 0 | EZ12: 0 | FA12: 0 | FB12: 0 | FC12: 1 | FD12: 0 | FE12: 0 | FF12: 0 | FG12: 0 | FH12: 0 | FI12: 0 | FJ12: 0 | FK12: 0 | FL12: 0 | FM12: =SUM(ES12:FL12) -> 2 | FN12: 2 | FO12: 1 | FP12: 1 | FQ12: 1 | FR12: 1 | FS12: 2 | FT12: 1 | FU12: 1 | FV12: 1 | FW12: 1 | FX12: 1 | FY12: 1 | FZ12: 1 | GA12: 2 | GB12: 1 | GC12: 1 | GD12: 1 | GE12: 1 | GF12: 1 | GG12: 1 | GH12: 1 | GI12: 1 | GJ12: 1 | GK12: 1 | GL12: 1 | GM12: 1 | GN12: 1 | GO12: 1 | GP12: 1 | GQ12: 1 | GR12: 1 | GS12: 1 | GT12: 1 | GU12: 1 | GV12: 1 | GW12: 1 | GX12: 1 | GY12: 1 | GZ12: 1 | HA12: 1 | HB12: =SUM(FN12:HA12) -> 43 | HC12: =HB12/40 -> 1.075 | HD12: 1 | HE12: 0 | HF12: 0 | HG12: 0 | HH12: 0 | HI12: 0 | HJ12: =SUM(HE12:HI12) -> 0 | HK12: 3 | HL12: 4 | HM12: 3 | HN12: 4 | HO12: 3 | HP12: 4 | HQ12: 3 | HR12: 3 | HS12: 4 | HT12: 3 | HU12: 3 | HV12: 4 | HW12: 3 | HX12: 3 | HY12: =SUM(HK12:HX12) -> 47 | HZ12: 2 | IA12: 2 | IB12: 2 | IC12: 2 | ID12: 2 | IE12: 2 | IF12: 2 | IG12: 2 | IH12: 2 | II12: 2 | IJ12: =SUM(HZ12:II12) -> 20 | IK12: 4 | IL12: 4 | IM12: 4 | IN12: 4 | IO12: 4 | IP12: 4 | IQ12: =SUM(IK12:IP12) -> 24 | IR12: =IQ12/6 -> 4 | IS12: 3 | IT12: 3 | IU12: 3 | IV12: 3 | IW12: 3 | IX12: 3 | IY12: 3 | IZ12: 3 | JA12: 3 | JB12: 3 | JC12: =SUM(IS12:JB12) -> 30
AK13: Min | AL13: =MIN(AL4:AL12) -> 5 | BZ13: Min | CA13: =MIN(CA4:CA12) -> 48 | CB13: =MIN(CB4:CB12) -> 1.2 | CH13: Min | CI13: =MIN(CI4:CI12) -> 1 | CW13: Min | CX13: =MIN(CX4:CX12) -> 30 | DH13: Min | DI13: =MIN(DI4:DI12) -> 4 | DO13: Min | DP13: =MIN(DP4:DP12) -> 6 | DQ13: =MIN(DQ4:DQ12) -> 1 | EA13: Min | EB13: =MIN(EB4:EB12) -> 10 | FL13: Min | FM13: =MIN(FM4:FM12) -> 2 | HA13: Min | HB13: =MIN(HB4:HB12) -> 43 | HC13: =MIN(HC4:HC12) -> 1.075 | HI13: Min | HJ13: =MIN(HJ4:HJ12) -> 0 | HX13: Min | HY13: =MIN(HY4:HY12) -> 23 | II13: Min | IJ13: =MIN(IJ4:IJ12) -> 8 | IP13: Min | IQ13: =MIN(IQ4:IQ12) -> 6 | IR13: =MIN(IR4:IR12) -> 1 | JC13: =MIN(JC4:JC12) -> 12
AK14: Max | AL14: =MAX(AL4:AL12) -> 71 | BZ14: Max | CA14: =MAX(CA4:CA12) -> 133 | CB14: =MAX(CB4:CB12) -> 3.325 | CH14: Max | CI14: =MAX(CI4:CI12) -> 5 | CW14: Max | CX14: =MAX(CX4:CX12) -> 57 | DH14: Max | DI14: =MAX(DI4:DI12) -> 35 | DO14: Max | DP14: =MAX(DP4:DP12) -> 29 | DQ14: =MAX(DQ4:DQ12) -> 4.8333333 | EA14: Max | EB14: =MAX(EB4:EB12) -> 30 | FL14: Max | FM14: =MAX(FM4:FM12) -> 53 | HA14: Max | HB14: =MAX(HB4:HB12) -> 108 | HC14: =MAX(HC4:HC12) -> 2.7 | HI14: Max | HJ14: =MAX(HJ4:HJ12) -> 5 | HX14: Max | HY14: =MAX(HY4:HY12) -> 56 | II14: Max | IJ14: =MAX(IJ4:IJ12) -> 27 | IP14: Max | IQ14: =MAX(IQ4:IQ12) -> 26 | IR14: =MAX(IR4:IR12) -> 4.3333333 | JC14: =MAX(JC4:JC12) -> 30
AK15: Mean | AL15: =AVERAGE(AL4:AL12) -> 34.444444 | BZ15: Mean | CA15: =AVERAGE(CA4:CA12) -> 82.777778 | CB15: =AVERAGE(CB4:CB12) -> 2.0694444 | CH15: Mean | CI15: =AVERAGE(CI4:CI12) -> 3 | CW15: Mean | CX15: =AVERAGE(CX4:CX12) -> 38.888889 | DH15: Mean | DI15: =AVERAGE(DI4:DI12) -> 17.555556 | DO15: Mean | DP15: =AVERAGE(DP4:DP12) -> 15.888889 | DQ15: =AVERAGE(DQ4:DQ12) -> 2.6481481 | EA15: Mean | EB15: =AVERAGE(EB4:EB12) -> 20.333333 | FL15: Mean | FM15: =AVERAGE(FM4:FM12) -> 28.666667 | HA15: Mean | HB15: =AVERAGE(HB4:HB12) -> 74.222222 | HC15: =AVERAGE(HC4:HC12) -> 1.8555556 | HI15: Mean | HJ15: =AVERAGE(HJ4:HJ12) -> 2.4444444 | HX15: Mean | HY15: =AVERAGE(HY4:HY12) -> 37 | II15: Mean | IJ15: =AVERAGE(IJ4:IJ12) -> 16.333333 | IP15: Mean | IQ15: =AVERAGE(IQ4:IQ12) -> 15.777778 | IR15: =AVERAGE(IR4:IR12) -> 2.6296296 | JC15: =AVERAGE(JC4:JC12) -> 20.333333
AK16: SD | AL16: =STDEV(AL4:AL12) -> 23.843821 | BZ16: SD | CA16: =STDEV(CA4:CA12) -> 28.375948 | CB16: =STDEV(CB4:CB12) -> 0.70939871 | CH16: SD | CI16: =STDEV(CI4:CI12) -> 1.7320508 | CW16: SD | CX16: =STDEV(CX4:CX12) -> 9.6104688 | DH16: SD | DI16: =STDEV(DI4:DI12) -> 9.2616293 | DO16: SD | DP16: =STDEV(DP4:DP12) -> 7.6720995 | DQ16: =STDEV(DQ4:DQ12) -> 1.2786833 | EA16: SD | EB16: =STDEV(EB4:EB12) -> 6.2849025 | FL16: SD | FM16: =STDEV(FM4:FM12) -> 20.081086 | HA16: SD | HB16: =STDEV(HB4:HB12) -> 24.468233 | HC16: =STDEV(HC4:HC12) -> 0.61170583 | HI16: SD | HJ16: =STDEV(HJ4:HJ12) -> 2.0069324 | HX16: SD | HY16: =STDEV(HY4:HY12) -> 10.700467 | II16: SD | IJ16: =STDEV(IJ4:IJ12) -> 5.8309519 | IP16: SD | IQ16: =STDEV(IQ4:IQ12) -> 7.3955692 | IR16: =STDEV(IR4:IR12) -> 1.2325949 | JC16: =STDEV(JC4:JC12) -> 6.2249498
A17: P08 | B17: BCI group | C17: 2,3 | D17: 1,2,3 | E17: 1,2,3 | F17: 1,2,3 | G17: 1,2,3 | H17: 1,2 | I17: 1,2,3 | J17: 1,2,3 | K17: 1,2 | L17: 1,2 | M17: 1,2 | N17: 1,2 | O17: 1,2 | P17: 2 | R17: 3 | S17: 1 | T17: 2 | U17: 2 | V17: 3 | W17: 2 | X17: 2 | Y17: 1 | Z17: 3 | AA17: 0 | AB17: 3 | AC17: 3 | AD17: 3 | AE17: 2 | AF17: 2 | AG17: 0 | AH17: 3 | AI17: 3 | AJ17: 2 | AK17: 3 | AL17: =SUM(R17:AK17) -> 43 | AM17: 2 | AN17: 2 | AO17: 2 | AP17: 3 | AQ17: 3 | AR17: 3 | AS17: 3 | AT17: 3 | AU17: 2 | AV17: 3 | AW17: 3 | AX17: 1 | AY17: 1 | AZ17: 2 | BA17: 2 | BB17: 1 | BC17: 2 | BD17: 2 | BE17: 3 | BF17: 2 | BG17: 1 | BH17: 2 | BI17: 2 | BJ17: 2 | BK17: 1 | BL17: 2 | BM17: 1 | BN17: 2 | BO17: 3 | BP17: 1 | BQ17: 2 | BR17: 2 | BS17: 1 | BT17: 2 | BU17: 3 | BV17: 2 | BW17: 1 | BX17: 3 | BY17: 2 | BZ17: 1 | CA17: =SUM(AM17:BZ17) -> 81 | CB17: =CA17/40 -> 2.025 | CC17: 1 | CD17: 1 | CE17: 0 | CF17: 1 | CG17: 1 | CH17: 0 | CI17: =SUM(CD17:CH17) -> 3 | CJ17: 4 | CK17: 4 | CL17: 2 | CM17: 4 | CN17: 2 | CO17: 3 | CP17: 3 | CQ17: 4 | CR17: 3 | CS17: 4 | CT17: 1 | CU17: 2 | CV17: 1 | CW17: 2 | CX17: =SUM(CC17:CW17) -> 46 | CY17: 2 | CZ17: 2 | DA17: 2 | DB17: 1 | DC17: 1 | DD17: 2 | DE17: 2 | DF17: 1 | DG17: 1 | DH17: 1 | DI17: =SUM(CY17:DH17) -> 15 | DJ17: 4 | DK17: 4 | DL17: 4 | DM17: 4 | DN17: 2 | DO17: 2 | DP17: =SUM(DJ17:DO17) -> 20 | DQ17: =DP17/6 -> 3.3333333 | DR17: 3 | DS17: 3 | DT17: 3 | DU17: 3 | DV17: 3 | DW17: 3 | DX17: 3 | DY17: 4 | DZ17: 3 | EA17: 4 | EB17: =SUM(DR17:EA17) -> 32 | ED17: 2,3 | EE17: 1,2,3 | EF17: 1,2,3 | EG17: 1,2,3 | EH17: 1,2,3 | EI17: 1,2,3 | EJ17: 1,2,3 | EK17: 1,2,3 | EL17: 1,2,3 | EM17: 1,2,3 | EN17: 1,2,3 | EO17: 1,2,3 | EP17: 1,2,3 | EQ17: 1,2,3 | ES17: 3 | ET17: 2 | EU17: 2 | EV17: 2 | EW17: 1 | EX17: 2 | EY17: 2 | EZ17: 1 | FA17: 2 | FB17: 2 | FC17: 2 | FD17: 2 | FE17: 0 | FF17: 1 | FG17: 2 | FH17: 0 | FI17: 2 | FJ17: 2 | FK17: 1 | FL17: 2 | FM17: =SUM(ES17:FL17) -> 33 | FN17: 3 | FO17: 2 | FP17: 2 | FQ17: 1 | FR17: 3 | FS17: 3 | FT17: 3 | FU17: 2 | FV17: 2 | FW17: 2 | FX17: 2 | FY17: 2 | FZ17: 1 | GA17: 1 | GB17: 2 | GC17: 2 | GD17: 3 | GE17: 2 | GF17: 1 | GG17: 1 | GH17: 1 | GI17: 2 | GJ17: 2 | GK17: 3 | GL17: 2 | GM17: 2 | GN17: 1 | GO17: 1 | GP17: 1 | GQ17: 2 | GR17: 3 | GS17: 2 | GT17: 3 | GU17: 3 | GV17: 3 | GW17: 3 | GX17: 1 | GY17: 3 | GZ17: 1 | HA17: 1 | HB17: =SUM(FN17:HA17) -> 80 | HC17: =HB17/40 -> 2 | HD17: 1 | HE17: 0 | HF17: 0 | HG17: 1 | HH17: 0 | HI17: 0 | HJ17: =SUM(HE17:HI17) -> 1 | HK17: 3 | HL17: 4 | HM17: 2 | HN17: 2 | HO17: 1 | HP17: 2 | HQ17: 3 | HR17: 3 | HS17: 4 | HT17: 4 | HU17: 3 | HV17: 3 | HW17: 2 | HX17: 3 | HY17: =SUM(HK17:HX17) -> 39 | HZ17: 2 | IA17: 3 | IB17: 2 | IC17: 1 | ID17: 2 | IE17: 2 | IF17: 2 | IG17: 2 | IH17: 2 | II17: 3 | IJ17: =SUM(HZ17:II17) -> 21 | IK17: 4 | IL17: 4 | IM17: 4 | IN17: 4 | IO17: 2 | IP17: 2 | IQ17: =SUM(IK17:IP17) -> 20 | IR17: =IQ17/6 -> 3.3333333 | IS17: 3 | IT17: 4 | IU17: 3 | IV17: 3 | IW17: 3 | IX17: 3 | IY17: 4 | IZ17: 3 | JA17: 3 | JB17: 3 | JC17: =SUM(IS17:JB17) -> 32
A18: P09 | C18: 2,3 | D18: 2 | E18: 1,2,3 | F18: 1,2,3 | G18: 2,3 | H18: 2,3 | I18: 2,3 | J18: 4 | K18: 4 | L18: 1,2,3 | M18: 1,2,3 | N18: 1,2,3 | O18: 1,2,3 | P18: 1,2,3 | R18: 1 | S18: 0 | T18: 1 | U18: 2 | V18: 2 | W18: 1 | X18: 1 | Y18: 2 | Z18: 2 | AA18: 2 | AB18: 3 | AC18: 4 | AD18: 3 | AE18: 3 | AF18: 3 | AG18: 0 | AH18: 1 | AI18: 3 | AJ18: 3 | AK18: 2 | AL18: =SUM(R18:AK18) -> 39 | AM18: 1 | AN18: 2 | AO18: 2 | AP18: 3 | AQ18: 2 | AR18: 2 | AS18: 3 | AT18: 2 | AU18: 2 | AV18: 2 | AW18: 1 | AX18: 1 | AY18: 2 | AZ18: 2 | BA18: 2 | BB18: 2 | BC18: 3 | BD18: 2 | BE18: 2 | BF18: 3 | BG18: 2 | BH18: 3 | BI18: 2 | BJ18: 3 | BK18: 3 | BL18: 3 | BM18: 2 | BN18: 1 | BO18: 2 | BP18: 1 | BQ18: 2 | BR18: 3 | BS18: 2 | BT18: 3 | BU18: 4 | BV18: 3 | BW18: 3 | BX18: 2 | BY18: 1 | BZ18: 1 | CA18: =SUM(AM18:BZ18) -> 87 | CB18: =CA18/40 -> 2.175 | CC18: 1 | CD18: 0 | CE18: 0 | CF18: 0 | CG18: 0 | CH18: 0 | CI18: =SUM(CD18:CH18) -> 0 | CJ18: 3 | CK18: 4 | CL18: 3 | CM18: 3 | CN18: 3 | CO18: 3 | CP18: 3 | CQ18: 3 | CR18: 3 | CS18: 3 | CT18: 3 | CU18: 3 | CV18: 2 | CW18: 3 | CX18: =SUM(CC18:CW18) -> 43 | CY18: 2 | CZ18: 2 | DA18: 2 | DB18: 2 | DC18: 2 | DD18: 2 | DE18: 2 | DF18: 2 | DG18: 2 | DH18: 2 | DI18: =SUM(CY18:DH18) -> 20 | DJ18: 4 | DK18: 2 | DL18: 1 | DM18: 2 | DN18: 1 | DO18: 5 | DP18: =SUM(DJ18:DO18) -> 15 | DQ18: =DP18/6 -> 2.5 | DR18: 3 | DS18: 3 | DT18: 3 | DU18: 3 | DV18: 3 | DW18: 3 | DX18: 3 | DY18: 2 | DZ18: 3 | EA18: 3 | EB18: =SUM(DR18:EA18) -> 29 | ED18: 2,3 | EE18: 2,3 | EF18: 1,2,3 | EG18: 1,2,3 | EH18: 2,3 | EI18: 2,3 | EJ18: 2,3 | EK18: 2,3 | EL18: 2,3 | EM18: 1,2,3 | EN18: 1,2,3 | EO18: 1,2,3 | EP18: 1,2,3 | EQ18: 2,3 | ES18: 2 | ET18: 2 | EU18: 1 | EV18: 2 | EW18: 2 | EX18: 1 | EY18: 0 | EZ18: 0 | FA18: 2 | FB18: 2 | FC18: 2 | FD18: 2 | FE18: 2 | FF18: 2 | FG18: 1 | FH18: 0 | FI18: 1 | FJ18: 2 | FK18: 2 | FL18: 2 | FM18: =SUM(ES18:FL18) -> 30 | FN18: 2 | FO18: 1 | FP18: 2 | FQ18: 2 | FR18: 2 | FS18: 2 | FT18: 2 | FU18: 2 | FV18: 2 | FW18: 2 | FX18: 1 | FY18: 2 | FZ18: 2 | GA18: 3 | GB18: 2 | GC18: 2 | GD18: 3 | GE18: 2 | GF18: 2 | GG18: 2 | GH18: 2 | GI18: 2 | GJ18: 2 | GK18: 2 | GL18: 3 | GM18: 2 | GN18: 1 | GO18: 1 | GP18: 2 | GQ18: 2 | GR18: 3 | GS18: 2 | GT18: 2 | GU18: 3 | GV18: 3 | GW18: 2 | GX18: 1 | GY18: 1 | GZ18: 1 | HA18: 1 | HB18: =SUM(FN18:HA18) -> 78 | HC18: =HB18/40 -> 1.95 | HD18: 1 | HE18: 0 | HF18: 1 | HG18: 0 | HH18: 0 | HI18: 0 | HJ18: =SUM(HE18:HI18) -> 1 | HK18: 3 | HL18: 3 | HM18: 2 | HN18: 3 | HO18: 2 | HP18: 3 | HQ18: 3 | HR18: 2 | HS18: 3 | HT18: 3 | HU18: 3 | HV18: 2 | HW18: 2 | HX18: 3 | HY18: =SUM(HK18:HX18) -> 37 | HZ18: 2 | IA18: 2 | IB18: 2 | IC18: 3 | ID18: 2 | IE18: 2 | IF18: 0 | IG18: 1 | IH18: 2 | II18: 2 | IJ18: =SUM(HZ18:II18) -> 18 | IK18: 4 | IL18: 4 | IM18: 4 | IN18: 4 | IO18: 4 | IP18: 4 | IQ18: =SUM(IK18:IP18) -> 24 | IR18: =IQ18/6 -> 4 | IS18: 2 | IT18: 3 | IU18: 3 | IV18: 3 | IW18: 3 | IX18: 3 | IY18: 2 | IZ18: 3 | JA18: 3 | JB18: 2 | JC18: =SUM(IS18:JB18) -> 27
A19: P10 | C19: 2,3 | D19: 1,2,3 | E19: 1,2,3 | F19: 1,2,3 | G19: 2,3 | H19: 2,3 | I19: 2,3 | J19: 1,2,3 | K19: 1,2,3 | L19: 1,2,3 | M19: 1,2,3 | N19: 1,2,3 | O19: 1,2,3 | P19: 1,2,3 | R19: 4 | S19: 4 | T19: 3 | U19: 3 | V19: 0 | W19: 3 | X19: 3 | Y19: 0 | Z19: 1 | AA19: 0 | AB19: 3 | AC19: 2 | AD19: 1 | AE19: 3 | AF19: 0 | AG19: 0 | AH19: 0 | AI19: 3 | AJ19: 3 | AK19: 3 | AL19: =SUM(R19:AK19) -> 39 | AM19: 3 | AN19: 2 | AO19: 3 | AP19: 3 | AQ19: 2 | AR19: 3 | AS19: 3 | AT19: 3 | AU19: 2 | AV19: 3 | AW19: 3 | AX19: 2 | AY19: 3 | AZ19: 1 | BA19: 2 | BB19: 3 | BC19: 3 | BD19: 3 | BE19: 2 | BF19: 2 | BG19: 3 | BH19: 3 | BI19: 3 | BJ19: 3 | BK19: 3 | BL19: 3 | BM19: 1 | BN19: 1 | BO19: 2 | BP19: 1 | BQ19: 3 | BR19: 1 | BS19: 3 | BT19: 3 | BU19: 3 | BV19: 3 | BW19: 2 | BX19: 3 | BY19: 1 | BZ19: 1 | CA19: =SUM(AM19:BZ19) -> 97 | CB19: =CA19/40 -> 2.425 | CC19: 1 | CD19: 0 | CE19: 0 | CF19: 0 | CG19: 1 | CH19: 0 | CI19: =SUM(CD19:CH19) -> 1 | CJ19: 4 | CK19: 4 | CL19: 4 | CM19: 2 | CN19: 2 | CO19: 2 | CP19: 2 | CQ19: 2 | CR19: 2 | CS19: 4 | CT19: 2 | CU19: 2 | CV19: 3 | CW19: 2 | CX19: =SUM(CC19:CW19) -> 40 | CY19: 2 | CZ19: 3 | DA19: 2 | DB19: 1 | DC19: 1 | DD19: 1 | DE19: 2 | DF19: 1 | DG19: 2 | DH19: 1 | DI19: =SUM(CY19:DH19) -> 16 | DJ19: 2 | DK19: 3 | DL19: 4 | DM19: 4 | DN19: 4 | DO19: 2 | DP19: =SUM(DJ19:DO19) -> 19 | DQ19: =DP19/6 -> 3.1666667 | DR19: 3 | DS19: 2 | DT19: 3 | DU19: 3 | DV19: 3 | DW19: 2 | DX19: 2 | DY19: 2 | DZ19: 3 | EA19: 2 | EB19: =SUM(DR19:EA19) -> 25 | ED19: 2,3 | EE19: 2,3 | EF19: 1,2,3 | EG19: 1,2,3 | EH19: 1,2,3 | EI19: 1,2,3 | EJ19: 2,3 | EK19: 1,2,3 | EL19: 1,2,3 | EM19: 1,2,3 | EN19: 1,2,3 | EO19: 1,2,3 | EP19: 1,2,3 | EQ19: 1,2,3 | ES19: 3 | ET19: 3 | EU19: 3 | EV19: 3 | EW19: 3 | EX19: 2 | EY19: 3 | EZ19: 3 | FA19: 1 | FB19: 0 | FC19: 3 | FD19: 3 | FE19: 0 | FF19: 3 | FG19: 0 | FH19: 0 | FI19: 0 | FJ19: 1 | FK19: 2 | FL19: 4 | FM19: =SUM(ES19:FL19) -> 40 | FN19: 2 | FO19: 1 | FP19: 3 | FQ19: 2 | FR19: 2 | FS19: 1 | FT19: 2 | FU19: 4 | FV19: 1 | FW19: 2 | FX19: 2 | FY19: 1 | FZ19: 2 | GA19: 2 | GB19: 2 | GC19: 3 | GD19: 3 | GE19: 3 | GF19: 3 | GG19: 3 | GH19: 3 | GI19: 3 | GJ19: 3 | GK19: 3 | GL19: 2 | GM19: 2 | GN19: 1 | GO19: 1 | GP19: 1 | GQ19: 2 | GR19: 2 | GS19: 1 | GT19: 3 | GU19: 4 | GV19: 4 | GW19: 3 | GX19: 2 | GY19: 1 | GZ19: 1 | HA19: 1 | HB19: =SUM(FN19:HA19) -> 87 | HC19: =HB19/40 -> 2.175 | HD19: 1 | HE19: 0 | HF19: 0 | HG19: 0 | HH19: 0 | HI19: 0 | HJ19: =SUM(HE19:HI19) -> 0 | HK19: 4 | HL19: 4 | HM19: 3 | HN19: 2 | HO19: 2 | HP19: 3 | HQ19: 2 | HR19: 2 | HS19: 2 | HT19: 3 | HU19: 2 | HV19: 2 | HW19: 1 | HX19: 1 | HY19: =SUM(HK19:HX19) -> 33 | HZ19: 2 | IA19: 2 | IB19: 3 | IC19: 0 | ID19: 2 | IE19: 0 | IF19: 1 | IG19: 1 | IH19: 2 | II19: 2 | IJ19: =SUM(HZ19:II19) -> 15 | IK19: 4 | IL19: 4 | IM19: 4 | IN19: 4 | IO19: 2 | IP19: 2 | IQ19: =SUM(IK19:IP19) -> 20 | IR19: =IQ19/6 -> 3.3333333 | IS19: 3 | IT19: 2 | IU19: 3 | IV19: 3 | IW19: 3 | IX19: 3 | IY19: 2 | IZ19: 2 | JA19: 2 | JB19: 3 | JC19: =SUM(IS19:JB19) -> 26
A20: P11 | C20: 2,3 | D20: 1,2,3 | E20: 1,2,3 | F20: 1,2,3 | G20: 2,3 | H20: 2,3, | I20: 2,3 | J20: 2,3 | K20: 2,3 | L20: 2,3 | M20: 1,2,3 | N20: 1,2,3 | O20: 2,3 | P20: 2,3 | R20: 2 | S20: 3 | T20: 0 | U20: 0 | V20: 0 | W20: 3 | X20: 3 | Y20: 3 | Z20: 0 | AA20: 0 | AB20: 0 | AC20: 2 | AD20: 3 | AE20: 3 | AF20: 1 | AG20: 0 | AH20: 0 | AI20: 0 | AJ20: 0 | AK20: 2 | AL20: =SUM(R20:AK20) -> 25 | AM20: 2 | AN20: 1 | AO20: 1 | AP20: 3 | AQ20: 1 | AR20: 1 | AS20: 3 | AT20: 2 | AU20: 1 | AV20: 1 | AW20: 3 | AX20: 1 | AY20: 1 | AZ20: 1 | BA20: 3 | BB20: 1 | BC20: 2 | BD20: 2 | BE20: 3 | BF20: 2 | BG20: 2 | BH20: 3 | BI20: 2 | BJ20: 1 | BK20: 1 | BL20: 3 | BM20: 1 | BN20: 1 | BO20: 1 | BP20: 1 | BQ20: 1 | BR20: 1 | BS20: 2 | BT20: 2 | BU20: 3 | BV20: 2 | BW20: 1 | BX20: 1 | BY20: 1 | BZ20: 1 | CA20: =SUM(AM20:BZ20) -> 66 | CB20: =CA20/40 -> 1.65 | CC20: 1 | CD20: 0 | CE20: 0 | CF20: 0 | CG20: 0 | CH20: 0 | CI20: =SUM(CD20:CH20) -> 0 | CJ20: 4 | CK20: 4 | CL20: 4 | CM20: 2 | CN20: 1 | CO20: 1 | CP20: 1 | CQ20: 2 | CR20: 3 | CS20: 3 | CT20: 2 | CU20: 3 | CV20: 2 | CW20: 2 | CX20: =SUM(CC20:CW20) -> 35 | CY20: 3 | CZ20: 1 | DA20: 3 | DB20: 1 | DC20: 1 | DD20: 3 | DE20: 1 | DF20: 3 | DG20: 2 | DH20: 2 | DI20: =SUM(CY20:DH20) -> 20 | DJ20: 4 | DK20: 4 | DL20: 2 | DM20: 4 | DN20: 4 | DO20: 2 | DP20: =SUM(DJ20:DO20) -> 20 | DQ20: =DP20/6 -> 3.3333333 | DR20: 3 | DS20: 3 | DT20: 2 | DU20: 3 | DV20: 3 | DW20: 3 | DX20: 3 | DY20: 4 | DZ20: 2 | EA20: 2 | EB20: =SUM(DR20:EA20) -> 28 | ED20: 2,3 | EE20: 1,2,3 | EF20: 1,2,3 | EG20: 2,3 | EH20: 2,3 | EI20: 2,3 | EJ20: 2,3 | EK20: 2,3 | EL20: 2,3 | EM20: 2,3 | EN20: 2,3 | EO20: 2,3 | EP20: 1,2,3 | EQ20: 2,3 | ES20: 3 | ET20: 2 | EU20: 0 | EV20: 0 | EW20: 0 | EX20: 3 | EY20: 3 | EZ20: 1 | FA20: 0 | FB20: 0 | FC20: 1 | FD20: 2 | FE20: 3 | FF20: 3 | FG20: 0 | FH20: 0 | FI20: 0 | FJ20: 0 | FK20: 0 | FL20: 2 | FM20: =SUM(ES20:FL20) -> 23 | FN20: 2 | FO20: 1 | FP20: 1 | FQ20: 3 | FR20: 1 | FS20: 1 | FT20: 2 | FU20: 2 | FV20: 1 | FW20: 1 | FX20: 3 | FY20: 3 | FZ20: 1 | GA20: 1 | GB20: 3 | GC20: 1 | GD20: 2 | GE20: 3 | GF20: 1 | GG20: 1 | GH20: 1 | GI20: 2 | GJ20: 2 | GK20: 1 | GL20: 1 | GM20: 1 | GN20: 1 | GO20: 1 | GP20: 1 | GQ20: 1 | GR20: 1 | GS20: 1 | GT20: 2 | GU20: 2 | GV20: 3 | GW20: 2 | GX20: 1 | GY20: 1 | GZ20: 1 | HA20: 1 | HB20: =SUM(FN20:HA20) -> 61 | HC20: =HB20/40 -> 1.525 | HD20: 1 | HE20: 0 | HF20: 0 | HG20: 0 | HH20: 0 | HI20: 0 | HJ20: =SUM(HE20:HI20) -> 0 | HK20: 4 | HL20: 4 | HM20: 4 | HN20: 4 | HO20: 4 | HP20: 4 | HQ20: 4 | HR20: 4 | HS20: 2 | HT20: 3 | HU20: 4 | HV20: 1 | HW20: 1 | HX20: 2 | HY20: =SUM(HK20:HX20) -> 45 | HZ20: 1 | IA20: 1 | IB20: 2 | IC20: 0 | ID20: 2 | IE20: 1 | IF20: 1 | IG20: 0 | IH20: 2 | II20: 3 | IJ20: =SUM(HZ20:II20) -> 13 | IK20: 4 | IL20: 4 | IM20: 4 | IN20: 4 | IO20: 4 | IP20: 4 | IQ20: =SUM(IK20:IP20) -> 24 | IR20: =IQ20/6 -> 4 | IS20: 2 | IT20: 3 | IU20: 1 | IV20: 1 | IW20: 2 | IX20: 2 | IY20: 1 | IZ20: 1 | JA20: 3 | JB20: 2 | JC20: =SUM(IS20:JB20) -> 18
A21: P12 | C21: 1,2,3 | D21: 1,2,3 | E21: 1,2,3 | F21: 1,2,3 | G21: 2,3 | H21: 1,2,3 | I21: 2,3 | J21: 2,3 | K21: 2,3 | L21: 1,2,3 | M21: 1,2,3 | N21: 1,2,3 | O21: 1,2,3 | P21: 2,3 | R21: 2 | S21: 3 | T21: 2 | U21: 3 | V21: 1 | W21: 2 | X21: 3 | Y21: 2 | Z21: 0 | AA21: 0 | AB21: 3 | AC21: 3 | AD21: 2 | AE21: 1 | AF21: 3 | AG21: 0 | AH21: 3 | AI21: 3 | AJ21: 3 | AK21: 1 | AL21: =SUM(R21:AK21) -> 40 | AM21: 3 | AN21: 3 | AO21: 2 | AP21: 2 | AQ21: 2 | AR21: 2 | AS21: 3 | AT21: 1 | AU21: 3 | AV21: 2 | AW21: 3 | AX21: 2 | AY21: 3 | AZ21: 3 | BA21: 3 | BB21: 3 | BC21: 4 | BD21: 3 | BE21: 3 | BF21: 2 | BG21: 2 | BH21: 3 | BI21: 2 | BJ21: 4 | BK21: 4 | BL21: 4 | BM21: 1 | BN21: 4 | BO21: 3 | BP21: 1 | BQ21: 3 | BR21: 3 | BS21: 4 | BT21: 4 | BU21: 4 | BV21: 3 | BW21: 2 | BX21: 4 | BY21: 3 | BZ21: 4 | CA21: =SUM(AM21:BZ21) -> 114 | CB21: =CA21/40 -> 2.85 | CC21: 1 | CD21: 1 | CE21: 0 | CF21: 1 | CG21: 0 | CH21: 0 | CI21: =SUM(CD21:CH21) -> 2 | CJ21: 1 | CK21: 2 | CL21: 2 | CM21: 2 | CN21: 3 | CO21: 2 | CP21: 2 | CQ21: 2 | CR21: 2 | CS21: 1 | CT21: 2 | CU21: 2 | CV21: 1 | CW21: 2 | CX21: =SUM(CC21:CW21) -> 31 | CY21: 1 | CZ21: 1 | DA21: 1 | DB21: 1 | DC21: 1 | DD21: 0 | DE21: 3 | DF21: 2 | DG21: 2 | DH21: 2 | DI21: =SUM(CY21:DH21) -> 14 | DJ21: 2 | DK21: 2 | DL21: 1 | DM21: 4 | DN21: 2 | DO21: 2 | DP21: =SUM(DJ21:DO21) -> 13 | DQ21: =DP21/6 -> 2.1666667 | DR21: 2 | DS21: 2 | DT21: 2 | DU21: 1 | DV21: 1 | DW21: 2 | DX21: 2 | DY21: 2 | DZ21: 1 | EA21: 2 | EB21: =SUM(DR21:EA21) -> 17 | ED21: 2,3 | EE21: 1,2,3 | EF21: 1,2,3 | EG21: 1,2,3 | EH21: 2,3 | EI21: 2,3 | EJ21: 2,3 | EK21: 2,3 | EL21: 2,3 | EM21: 2,3 | EN21: 1,2,3 | EO21: 1,2,3 | EP21: 1,2,3 | EQ21: 2,3 | ES21: 3 | ET21: 1 | EU21: 2 | EV21: 3 | EW21: 3 | EX21: 3 | EY21: 1 | EZ21: 3 | FA21: 4 | FB21: 3 | FC21: 3 | FD21: 3 | FE21: 3 | FF21: 4 | FG21: 3 | FH21: 0 | FI21: 3 | FJ21: 3 | FK21: 4 | FL21: 2 | FM21: =SUM(ES21:FL21) -> 54 | FN21: 3 | FO21: 2 | FP21: 2 | FQ21: 3 | FR21: 3 | FS21: 4 | FT21: 4 | FU21: 2 | FV21: 4 | FW21: 3 | FX21: 2 | FY21: 2 | FZ21: 3 | GA21: 4 | GB21: 3 | GC21: 3 | GD21: 4 | GE21: 3 | GF21: 2 | GG21: 2 | GH21: 2 | GI21: 3 | GJ21: 3 | GK21: 3 | GL21: 3 | GM21: 3 | GN21: 1 | GO21: 4 | GP21: 3 | GQ21: 1 | GR21: 3 | GS21: 3 | GT21: 3 | GU21: 2 | GV21: 4 | GW21: 4 | GX21: 2 | GY21: 4 | GZ21: 1 | HA21: 1 | HB21: =SUM(FN21:HA21) -> 111 | HC21: =HB21/40 -> 2.775 | HD21: 1 | HE21: 1 | HF21: 0 | HG21: 1 | HH21: 0 | HI21: 1 | HJ21: =SUM(HE21:HI21) -> 3 | HK21: 1 | HL21: 0 | HM21: 0 | HN21: 0 | HO21: 3 | HP21: 3 | HQ21: 3 | HR21: 3 | HS21: 3 | HT21: 4 | HU21: 4 | HV21: 2 | HW21: 4 | HX21: 4 | HY21: =SUM(HK21:HX21) -> 34 | HZ21: 2 | IA21: 1 | IB21: 1 | IC21: 0 | ID21: 1 | IE21: 0 | IF21: 1 | IG21: 0 | IH21: 0 | II21: 1 | IJ21: =SUM(HZ21:II21) -> 7 | IK21: 2 | IL21: 2 | IM21: 2 | IN21: 2 | IO21: 1 | IP21: 2 | IQ21: =SUM(IK21:IP21) -> 11 | IR21: =IQ21/6 -> 1.8333333 | IS21: 2 | IT21: 2 | IU21: 1 | IV21: 2 | IW21: 2 | IX21: 1 | IY21: 2 | IZ21: 3 | JA21: 1 | JB21: 2 | JC21: =SUM(IS21:JB21) -> 18
A22: P13 | C22: 2,3 | D22: 1,2,3 | E22: 1,2,3 | F22: 1,2,3 | G22: 1,2,3 | H22: 1,2,3 | I22: 2,3 | J22: 1,2,3 | K22: 1,2,3 | L22: 1,2,3 | M22: 1,2,3 | N22: 1,2,3 | O22: 1,2,3 | P22: 1,2,3 | R22: 3 | S22: 3 | T22: 3 | U22: 3 | V22: 3 | W22: 3 | X22: 3 | Y22: 2 | Z22: 2 | AA22: 0 | AB22: 2 | AC22: 1 | AD22: 2 | AE22: 2 | AF22: 3 | AG22: 0 | AH22: 2 | AI22: 3 | AJ22: 3 | AK22: 0 | AL22: =SUM(R22:AK22) -> 43 | AM22: 2 | AN22: 2 | AO22: 2 | AP22: 3 | AQ22: 3 | AR22: 3 | AS22: 3 | AT22: 1 | AU22: 2 | AV22: 3 | AW22: 3 | AX22: 1 | AY22: 2 | AZ22: 3 | BA22: 1 | BB22: 3 | BC22: 3 | BD22: 3 | BE22: 3 | BF22: 3 | BG22: 2 | BH22: 1 | BI22: 1 | BJ22: 3 | BK22: 2 | BL22: 2 | BM22: 1 | BN22: 1 | BO22: 1 | BP22: 3 | BQ22: 3 | BR22: 3 | BS22: 2 | BT22: 3 | BU22: 4 | BV22: 2 | BW22: 2 | BX22: 4 | BY22: 1 | BZ22: 1 | CA22: =SUM(AM22:BZ22) -> 91 | CB22: =CA22/40 -> 2.275 | CC22: 1 | CD22: 1 | CE22: 1 | CF22: 1 | CG22: 1 | CH22: 0 | CI22: =SUM(CD22:CH22) -> 4 | CJ22: 4 | CK22: 3 | CL22: 2 | CM22: 2 | CN22: 2 | CO22: 2 | CP22: 2 | CQ22: 2 | CR22: 3 | CS22: 3 | CT22: 3 | CU22: 2 | CV22: 3 | CW22: 2 | CX22: =SUM(CC22:CW22) -> 44 | CY22: 2 | CZ22: 2 | DA22: 2 | DB22: 0 | DC22: 2 | DD22: 1 | DE22: 1 | DF22: 1 | DG22: 1 | DH22: 1 | DI22: =SUM(CY22:DH22) -> 13 | DJ22: 2 | DK22: 2 | DL22: 2 | DM22: 2 | DN22: 2 | DO22: 2 | DP22: =SUM(DJ22:DO22) -> 12 | DQ22: =DP22/6 -> 2 | DR22: 2 | DS22: 2 | DT22: 2 | DU22: 3 | DV22: 3 | DW22: 2 | DX22: 2 | DY22: 2 | DZ22: 2 | EA22: 2 | EB22: =SUM(DR22:EA22) -> 22 | ED22: 2,3 | EE22: 1,2,3 | EF22: 1,2,3 | EG22: 1,2,3 | EH22: 1,2,3 | EI22: 1,2,3 | EJ22: 2,3 | EK22: 1,2,3 | EL22: 1,2,3 | EM22: 1,2,3 | EN22: 1,2,3 | EO22: 1,2,3 | EP22: 1,2,3 | EQ22: 1,2,3 | ES22: 3 | ET22: 2 | EU22: 0 | EV22: 3 | EW22: 0 | EX22: 3 | EY22: 3 | EZ22: 1 | FA22: 2 | FB22: 1 | FC22: 3 | FD22: 2 | FE22: 2 | FF22: 2 | FG22: 3 | FH22: 0 | FI22: 1 | FJ22: 3 | FK22: 2 | FL22: 3 | FM22: =SUM(ES22:FL22) -> 39 | FN22: 2 | FO22: 1 | FP22: 1 | FQ22: 2 | FR22: 2 | FS22: 2 | FT22: 3 | FU22: 3 | FV22: 2 | FW22: 2 | FX22: 2 | FY22: 2 | FZ22: 2 | GA22: 1 | GB22: 2 | GC22: 3 | GD22: 3 | GE22: 2 | GF22: 2 | GG22: 2 | GH22: 3 | GI22: 3 | GJ22: 3 | GK22: 1 | GL22: 3 | GM22: 3 | GN22: 1 | GO22: 1 | GP22: 1 | GQ22: 3 | GR22: 3 | GS22: 2 | GT22: 3 | GU22: 3 | GV22: 4 | GW22: 3 | GX22: 1 | GY22: 2 | GZ22: 1 | HA22: 1 | HB22: =SUM(FN22:HA22) -> 86 | HC22: =HB22/40 -> 2.15 | HD22: 1 | HE22: 0 | HF22: 1 | HG22: 1 | HH22: 1 | HI22: 0 | HJ22: =SUM(HE22:HI22) -> 3 | HK22: 3 | HL22: 2 | HM22: 2 | HN22: 2 | HO22: 1 | HP22: 3 | HQ22: 3 | HR22: 2 | HS22: 3 | HT22: 2 | HU22: 2 | HV22: 2 | HW22: 2 | HX22: 2 | HY22: =SUM(HK22:HX22) -> 31 | HZ22: 2 | IA22: 2 | IB22: 2 | IC22: 2 | ID22: 1 | IE22: 1 | IF22: 1 | IG22: 1 | IH22: 2 | II22: 2 | IJ22: =SUM(HZ22:II22) -> 16 | IK22: 2 | IL22: 2 | IM22: 2 | IN22: 2 | IO22: 2 | IP22: 2 | IQ22: =SUM(IK22:IP22) -> 12 | IR22: =IQ22/6 -> 2 | IS22: 3 | IT22: 2 | IU22: 2 | IV22: 2 | IW22: 2 | IX22: 2 | IY22: 1 | IZ22: 2 | JA22: 2 | JB22: 2 | JC22: =SUM(IS22:JB22) -> 20
A23: P14 | C23: 2,3 | D23: 1,2,3 | E23: 1,2,3 | F23: 1,2,3 | G23: 2,3 | H23: 2,3 | I23: 2,3 | J23: 2,3 | K23: 2,3 | L23: 1,2,3 | M23: 1,2,3 | N23: 1,2,3 | O23: 1,2,3 | P23: 2,3 | R23: 3 | S23: 3 | T23: 3 | U23: 3 | V23: 3 | W23: 3 | X23: 3 | Y23: 3 | Z23: 3 | AA23: 0 | AB23: 3 | AC23: 3 | AD23: 3 | AE23: 3 | AF23: 3 | AG23: 0 | AH23: 3 | AI23: 3 | AJ23: 3 | AK23: 4 | AL23: =SUM(R23:AK23) -> 55 | AM23: 3 | AN23: 3 | AO23: 3 | AP23: 3 | AQ23: 3 | AR23: 3 | AS23: 3 | AT23: 3 | AU23: 3 | AV23: 3 | AW23: 3 | AX23: 1 | AY23: 3 | AZ23: 3 | BA23: 3 | BB23: 3 | BC23: 3 | BD23: 3 | BE23: 3 | BF23: 3 | BG23: 3 | BH23: 4 | BI23: 3 | BJ23: 2 | BK23: 3 | BL23: 3 | BM23: 1 | BN23: 2 | BO23: 3 | BP23: 1 | BQ23: 3 | BR23: 1 | BS23: 2 | BT23: 2 | BU23: 4 | BV23: 3 | BW23: 2 | BX23: 4 | BY23: 1 | BZ23: 1 | CA23: =SUM(AM23:BZ23) -> 106 | CB23: =CA23/40 -> 2.65 | CC23: 1 | CD23: 1 | CE23: 0 | CF23: 1 | CG23: 1 | CH23: 0 | CI23: =SUM(CD23:CH23) -> 3 | CJ23: 3 | CK23: 2 | CL23: 2 | CM23: 2 | CN23: 2 | CO23: 3 | CP23: 3 | CQ23: 3 | CR23: 3 | CS23: 3 | CT23: 2 | CU23: 2 | CV23: 2 | CW23: 3 | CX23: =SUM(CC23:CW23) -> 42 | CY23: 2 | CZ23: 1 | DA23: 2 | DB23: 1 | DC23: 1 | DD23: 2 | DE23: 1 | DF23: 1 | DG23: 2 | DH23: 1 | DI23: =SUM(CY23:DH23) -> 14 | DJ23: 2 | DK23: 2 | DL23: 2 | DM23: 2 | DN23: 2 | DO23: 2 | DP23: =SUM(DJ23:DO23) -> 12 | DQ23: =DP23/6 -> 2 | DR23: 2 | DS23: 2 | DT23: 2 | DU23: 2 | DV23: 2 | DW23: 2 | DX23: 2 | DY23: 2 | DZ23: 2 | EA23: 2 | EB23: =SUM(DR23:EA23) -> 20 | ED23: 2,3 | EE23: 1,2,3 | EF23: 1,2,3 | EG23: 1,2,3 | EH23: 2,3 | EI23: 2,3 | EJ23: 2,3 | EK23: 2,3 | EL23: 2,3 | EM23: 1,2,3 | EN23: 1,2,3 | EO23: 1,2,3 | EP23: 1,2,3 | EQ23: 2,3 | ES23: 3 | ET23: 2 | EU23: 2 | EV23: 3 | EW23: 3 | EX23: 3 | EY23: 3 | EZ23: 3 | FA23: 0 | FB23: 3 | FC23: 3 | FD23: 3 | FE23: 3 | FF23: 3 | FG23: 3 | FH23: 0 | FI23: 3 | FJ23: 3 | FK23: 3 | FL23: 3 | FM23: =SUM(ES23:FL23) -> 52 | FN23: 3 | FO23: 3 | FP23: 3 | FQ23: 2 | FR23: 2 | FS23: 3 | FT23: 3 | FU23: 3 | FV23: 4 | FW23: 3 | FX23: 3 | FY23: 3 | FZ23: 1 | GA23: 1 | GB23: 1 | GC23: 3 | GD23: 3 | GE23: 3 | GF23: 2 | GG23: 3 | GH23: 3 | GI23: 3 | GJ23: 3 | GK23: 4 | GL23: 3 | GM23: 3 | GN23: 1 | GO23: 2 | GP23: 2 | GQ23: 1 | GR23: 1 | GS23: 1 | GT23: 1 | GU23: 1 | GV23: 3 | GW23: 2 | GX23: 1 | GY23: 3 | GZ23: 1 | HA23: 1 | HB23: =SUM(FN23:HA23) -> 92 | HC23: =HB23/40 -> 2.3 | HD23: 1 | HE23: 1 | HF23: 0 | HG23: 0 | HH23: 0 | HI23: 0 | HJ23: =SUM(HE23:HI23) -> 1 | HK23: 3 | HL23: 3 | HM23: 3 | HN23: 3 | HO23: 2 | HP23: 2 | HQ23: 2 | HR23: 2 | HS23: 3 | HT23: 3 | HU23: 3 | HV23: 3 | HW23: 3 | HX23: 2 | HY23: =SUM(HK23:HX23) -> 37 | HZ23: 1 | IA23: 2 | IB23: 2 | IC23: 1 | ID23: 1 | IE23: 2 | IF23: 2 | IG23: 2 | IH23: 2 | II23: 1 | IJ23: =SUM(HZ23:II23) -> 16 | IK23: 2 | IL23: 2 | IM23: 2 | IN23: 2 | IO23: 2 | IP23: 2 | IQ23: =SUM(IK23:IP23) -> 12 | IR23: =IQ23/6 -> 2 | IS23: 3 | IT23: 3 | IU23: 2 | IV23: 3 | IW23: 3 | IX23: 2 | IY23: 2 | IZ23: 2 | JA23: 2 | JB23: 3 | JC23: =SUM(IS23:JB23) -> 25
A24: P15 | C24: 2,3 | D24: 1,2,3 | E24: 1,2,3 | F24: 1,2,3 | G24: 1,2,3 | H24: 2,3 | I24: 2,3 | J24: 2,3 | K24: 2,3 | L24: 1,2,3 | M24: 2,3 | N24: 1,2,3 | O24: 1,2,3 | P24: 2,3 | R24: 3 | S24: 3 | T24: 3 | U24: 3 | V24: 3 | W24: 3 | X24: 3 | Y24: 3 | Z24: 4 | AA24: 3 | AB24: 3 | AC24: 3 | AD24: 2 | AE24: 3 | AF24: 3 | AG24: 1 | AH24: 2 | AI24: 3 | AJ24: 3 | AK24: 1 | AL24: =SUM(R24:AK24) -> 55 | AM24: 2 | AN24: 1 | AO24: 3 | AP24: 2 | AQ24: 2 | AR24: 3 | AS24: 3 | AT24: 2 | AU24: 2 | AV24: 3 | AW24: 2 | AX24: 2 | AY24: 3 | AZ24: 3 | BA24: 3 | BB24: 3 | BC24: 2 | BD24: 2 | BE24: 2 | BF24: 3 | BG24: 2 | BH24: 3 | BI24: 2 | BJ24: 3 | BK24: 3 | BL24: 3 | BM24: 1 | BN24: 2 | BO24: 3 | BP24: 1 | BQ24: 3 | BR24: 2 | BS24: 2 | BT24: 1 | BU24: 4 | BV24: 3 | BW24: 2 | BX24: 3 | BY24: 1 | BZ24: 1 | CA24: =SUM(AM24:BZ24) -> 93 | CB24: =CA24/40 -> 2.325 | CC24: 1 | CD24: 1 | CE24: 1 | CF24: 0 | CG24: 0 | CH24: 0 | CI24: =SUM(CD24:CH24) -> 2 | CJ24: 3 | CK24: 3 | CL24: 2 | CM24: 2 | CN24: 4 | CO24: 3 | CP24: 3 | CQ24: 3 | CR24: 3 | CS24: 3 | CT24: 3 | CU24: 2 | CV24: 3 | CW24: 2 | CX24: =SUM(CC24:CW24) -> 44 | CY24: 1 | CZ24: 2 | DA24: 2 | DB24: 0 | DC24: 0 | DD24: 1 | DE24: 1 | DF24: 2 | DG24: 2 | DH24: 2 | DI24: =SUM(CY24:DH24) -> 13 | DJ24: 2 | DK24: 2 | DL24: 4 | DM24: 2 | DN24: 2 | DO24: 2 | DP24: =SUM(DJ24:DO24) -> 14 | DQ24: =DP24/6 -> 2.3333333 | DR24: 3 | DS24: 3 | DT24: 2 | DU24: 3 | DV24: 2 | DW24: 2 | DX24: 2 | DY24: 2 | DZ24: 3 | EA24: 2 | EB24: =SUM(DR24:EA24) -> 24 | ED24: 2,3 | EE24: 1,2,3 | EF24: 1,2,3 | EG24: 1,2,3 | EH24: 2,3 | EI24: 2,3 | EJ24: 2,3 | EK24: 2,3 | EL24: 2,3 | EM24: 1,2,3 | EN24: 1,2,3 | EO24: 1,2,3 | EP24: 1,2,3 | EQ24: 2,3 | ES24: 3 | ET24: 3 | EU24: 3 | EV24: 3 | EW24: 3 | EX24: 3 | EY24: 3 | EZ24: 0 | FA24: 2 | FB24: 2 | FC24: 3 | FD24: 3 | FE24: 2 | FF24: 3 | FG24: 3 | FH24: 0 | FI24: 3 | FJ24: 3 | FK24: 3 | FL24: 0 | FM24: =SUM(ES24:FL24) -> 48 | FN24: 3 | FO24: 1 | FP24: 2 | FQ24: 3 | FR24: 3 | FS24: 2 | FT24: 2 | FU24: 1 | FV24: 3 | FW24: 3 | FX24: 2 | FY24: 3 | FZ24: 2 | GA24: 3 | GB24: 3 | GC24: 2 | GD24: 2 | GE24: 2 | GF24: 2 | GG24: 3 | GH24: 2 | GI24: 3 | GJ24: 3 | GK24: 3 | GL24: 3 | GM24: 1 | GN24: 1 | GO24: 2 | GP24: 3 | GQ24: 2 | GR24: 3 | GS24: 2 | GT24: 2 | GU24: 1 | GV24: 2 | GW24: 3 | GX24: 2 | GY24: 3 | GZ24: 1 | HA24: 1 | HB24: =SUM(FN24:HA24) -> 90 | HC24: =HB24/40 -> 2.25 | HD24: 1 | HE24: 0 | HF24: 0 | HG24: 0 | HH24: 0 | HI24: 0 | HJ24: =SUM(HE24:HI24) -> 0 | HK24: 3 | HL24: 3 | HM24: 3 | HN24: 3 | HO24: 3 | HP24: 3 | HQ24: 3 | HR24: 3 | HS24: 3 | HT24: 3 | HU24: 2 | HV24: 1 | HW24: 2 | HX24: 2 | HY24: =SUM(HK24:HX24) -> 37 | HZ24: 2 | IA24: 2 | IB24: 2 | IC24: 1 | ID24: 2 | IE24: 1 | IF24: 2 | IG24: 1 | IH24: 2 | II24: 2 | IJ24: =SUM(HZ24:II24) -> 17 | IK24: 2 | IL24: 2 | IM24: 2 | IN24: 2 | IO24: 2 | IP24: 2 | IQ24: =SUM(IK24:IP24) -> 12 | IR24: =IQ24/6 -> 2 | IS24: 3 | IT24: 2 | IU24: 2 | IV24: 2 | IW24: 2 | IX24: 2 | IY24: 2 | IZ24: 3 | JA24: 3 | JB24: 2 | JC24: =SUM(IS24:JB24) -> 23
A25: P26 | C25: 1 | D25: 1 | E25: 2 | F25: 2 | G25: 1 | H25: 1 | I25: 3 | J25: 3 | K25: 5 | L25: 1 | M25: 3 | N25: 6 | O25: 2 | P25: 3 | R25: 2 | S25: 3 | T25: 1 | U25: 3 | V25: 2 | W25: 2 | X25: 2 | Y25: 1 | Z25: 1 | AA25: 0 | AB25: 3 | AC25: 2 | AD25: 1 | AE25: 2 | AF25: 1 | AG25: 0 | AH25: 1 | AI25: 3 | AJ25: 3 | AK25: 3 | AL25: =SUM(R25:AK25) -> 36 | AM25: 3 | AN25: 2 | AO25: 2 | AP25: 2 | AQ25: 1 | AR25: 3 | AS25: 2 | AT25: 3 | AU25: 2 | AV25: 1 | AW25: 2 | AX25: 3 | AY25: 3 | AZ25: 4 | BA25: 1 | BB25: 2 | BC25: 3 | BD25: 3 | BE25: 3 | BF25: 4 | BG25: 4 | BH25: 4 | BI25: 4 | BJ25: 3 | BK25: 2 | BL25: 3 | BM25: 1 | BN25: 2 | BO25: 3 | BP25: 3 | BQ25: 2 | BR25: 1 | BS25: 2 | BT25: 1 | BU25: 3 | BV25: 1 | BW25: 2 | BX25: 3 | BY25: 1 | BZ25: 1 | CA25: =SUM(AM25:BZ25) -> 95 | CB25: =CA25/40 -> 2.375 | CC25: 1 | CD25: 1 | CE25: 1 | CF25: 1 | CG25: 1 | CH25: 0 | CI25: =SUM(CD25:CH25) -> 4 | CJ25: 2 | CK25: 2 | CL25: 1 | CM25: 3 | CN25: 1 | CO25: 1 | CP25: 2 | CQ25: 2 | CR25: 4 | CS25: 2 | CT25: 2 | CU25: 4 | CV25: 2 | CW25: 2 | CX25: =SUM(CC25:CW25) -> 39 | CY25: 1 | CZ25: 1 | DA25: 2 | DB25: 1 | DC25: 1 | DD25: 1 | DE25: 2 | DF25: 1 | DG25: 1 | DH25: 1 | DI25: =SUM(CY25:DH25) -> 12 | DJ25: 1 | DK25: 1 | DL25: 1 | DM25: 1 | DN25: 5 | DO25: 5 | DP25: =SUM(DJ25:DO25) -> 14 | DQ25: =DP25/6 -> 2.3333333 | DR25: 2 | DS25: 2 | DT25: 2 | DU25: 2 | DV25: 1 | DW25: 2 | DX25: 1 | DY25: 2 | DZ25: 2 | EA25: 1 | EB25: =SUM(DR25:EA25) -> 17 | ED25: 1 | EE25: 1 | EF25: 3 | EG25: 3 | EH25: 1 | EI25: 3 | EJ25: 3 | EK25: 2 | EL25: 5 | EM25: 1 | EN25: 3 | EO25: 6 | EP25: 1 | EQ25: 3 | ES25: 2 | ET25: 2 | EU25: 2 | EV25: 2 | EW25: 2 | EX25: 1 | EY25: 1 | EZ25: 2 | FA25: 1 | FB25: 0 | FC25: 2 | FD25: 2 | FE25: 1 | FF25: 1 | FG25: 0 | FH25: 0 | FI25: 0 | FJ25: 2 | FK25: 2 | FL25: 2 | FM25: =SUM(ES25:FL25) -> 27 | FN25: 3 | FO25: 2 | FP25: 3 | FQ25: 2 | FR25: 1 | FS25: 3 | FT25: 3 | FU25: 3 | FV25: 2 | FW25: 1 | FX25: 2 | FY25: 2 | FZ25: 3 | GA25: 3 | GB25: 2 | GC25: 2 | GD25: 3 | GE25: 2 | GF25: 3 | GG25: 3 | GH25: 2 | GI25: 2 | GJ25: 1 | GK25: 2 | GL25: 1 | GM25: 2 | GN25: 1 | GO25: 2 | GP25: 2 | GQ25: 2 | GR25: 1 | GS25: 1 | GT25: 1 | GU25: 1 | GV25: 2 | GW25: 1 | GX25: 2 | GY25: 2 | GZ25: 1 | HA25: 1 | HB25: =SUM(FN25:HA25) -> 78 | HC25: =HB25/40 -> 1.95 | HD25: 1 | HE25: 1 | HF25: 1 | HG25: 0 | HH25: 0 | HI25: 0 | HJ25: =SUM(HE25:HI25) -> 2 | HK25: 3 | HL25: 2 | HM25: 1 | HN25: 4 | HO25: 2 | HP25: 2 | HQ25: 2 | HR25: 2 | HS25: 4 | HT25: 2 | HU25: 2 | HV25: 3 | HW25: 1 | HX25: 2 | HY25: =SUM(HK25:HX25) -> 32 | HZ25: 2 | IA25: 2 | IB25: 1 | IC25: 1 | ID25: 1 | IE25: 1 | IF25: 2 | IG25: 2 | IH25: 1 | II25: 2 | IJ25: =SUM(HZ25:II25) -> 15 | IK25: 2 | IL25: 2 | IM25: 2 | IN25: 2 | IO25: 2 | IP25: 2 | IQ25: =SUM(IK25:IP25) -> 12 | IR25: =IQ25/6 -> 2 | IS25: 2 | IT25: 2 | IU25: 2 | IV25: 2 | IW25: 1 | IX25: 1 | IY25: 1 | IZ25: 1 | JA25: 1 | JB25: 2 | JC25: =SUM(IS25:JB25) -> 15
